return { { ["x"] = 0, ["meta"] = { ["fields"] = {  }, ["inventory"] = {  } }, ["param2"] = 0, ["y"] = 0, ["param1"] = 10, ["z"] = 0, ["name"] = "default:water_source" }, { ["x"] = 0, ["meta"] = { ["fields"] = {  }, ["inventory"] = {  } }, ["param2"] = 0, ["y"] = 0, ["param1"] = 10, ["z"] = 1, ["name"] = "default:water_source" }, { ["x"] = 0, ["meta"] = { ["fields"] = {  }, ["inventory"] = {  } }, ["param2"] = 0, ["y"] = 0, ["param1"] = 10, ["z"] = 2, ["name"] = "default:water_source" }, { ["x"] = 0, ["meta"] = { ["fields"] = {  }, ["inventory"] = {  } }, ["param2"] = 0, ["y"] = 0, ["param1"] = 10, ["z"] = 3, ["name"] = "default:water_source" }, { ["x"] = 0, ["meta"] = { ["fields"] = {  }, ["inventory"] = {  } }, ["param2"] = 0, ["y"] = 0, ["param1"] = 10, ["z"] = 4, ["name"] = "default:water_source" }, { ["x"] = 0, ["meta"] = { ["fields"] = {  }, ["inventory"] = {  } }, ["param2"] = 0, ["y"] = 0, ["param1"] = 10, ["z"] = 5, ["name"] = "default:water_source" }, { ["x"] = 0, ["meta"] = { ["fields"] = {  }, ["inventory"] = {  } }, ["param2"] = 0, ["y"] = 0, ["param1"] = 10, ["z"] = 6, ["name"] = "default:water_source" }, { ["x"] = 0, ["meta"] = { ["fields"] = {  }, ["inventory"] = {  } }, ["param2"] = 240, ["y"] = 0, ["param1"] = 10, ["z"] = 7, ["name"] = "default:water_source" }, { ["x"] = 0, ["meta"] = { ["fields"] = {  }, ["inventory"] = {  } }, ["param2"] = 240, ["y"] = 0, ["param1"] = 10, ["z"] = 8, ["name"] = "default:water_source" }, { ["x"] = 0, ["meta"] = { ["fields"] = {  }, ["inventory"] = {  } }, ["param2"] = 240, ["y"] = 0, ["param1"] = 10, ["z"] = 9, ["name"] = "default:water_source" }, { ["x"] = 0, ["meta"] = { ["fields"] = {  }, ["inventory"] = {  } }, ["param2"] = 240, ["y"] = 0, ["param1"] = 10, ["z"] = 10, ["name"] = "default:water_source" }, { ["x"] = 0, ["meta"] = { ["fields"] = {  }, ["inventory"] = {  } }, ["param2"] = 240, ["y"] = 0, ["param1"] = 10, ["z"] = 11, ["name"] = "default:water_source" }, { ["x"] = 0, ["meta"] = { ["fields"] = {  }, ["inventory"] = {  } }, ["param2"] = 240, ["y"] = 0, ["param1"] = 10, ["z"] = 12, ["name"] = "default:water_source" }, { ["x"] = 0, ["meta"] = { ["fields"] = {  }, ["inventory"] = {  } }, ["param2"] = 240, ["y"] = 0, ["param1"] = 10, ["z"] = 13, ["name"] = "default:water_source" }, { ["x"] = 0, ["meta"] = { ["fields"] = {  }, ["inventory"] = {  } }, ["param2"] = 240, ["y"] = 0, ["param1"] = 10, ["z"] = 14, ["name"] = "default:water_source" }, { ["x"] = 0, ["meta"] = { ["fields"] = {  }, ["inventory"] = {  } }, ["param2"] = 240, ["y"] = 0, ["param1"] = 10, ["z"] = 15, ["name"] = "default:water_source" }, { ["x"] = 0, ["meta"] = { ["fields"] = {  }, ["inventory"] = {  } }, ["param2"] = 240, ["y"] = 0, ["param1"] = 10, ["z"] = 16, ["name"] = "default:water_source" }, { ["x"] = 0, ["meta"] = { ["fields"] = {  }, ["inventory"] = {  } }, ["param2"] = 240, ["y"] = 0, ["param1"] = 10, ["z"] = 17, ["name"] = "default:water_source" }, { ["x"] = 0, ["meta"] = { ["fields"] = {  }, ["inventory"] = {  } }, ["param2"] = 240, ["y"] = 0, ["param1"] = 10, ["z"] = 18, ["name"] = "default:water_source" }, { ["x"] = 0, ["meta"] = { ["fields"] = {  }, ["inventory"] = {  } }, ["param2"] = 240, ["y"] = 0, ["param1"] = 10, ["z"] = 19, ["name"] = "default:water_source" }, { ["x"] = 0, ["meta"] = { ["fields"] = {  }, ["inventory"] = {  } }, ["param2"] = 240, ["y"] = 0, ["param1"] = 10, ["z"] = 20, ["name"] = "default:water_source" }, { ["x"] = 0, ["meta"] = { ["fields"] = {  }, ["inventory"] = {  } }, ["param2"] = 240, ["y"] = 0, ["param1"] = 10, ["z"] = 21, ["name"] = "default:water_source" }, { ["x"] = 0, ["meta"] = { ["fields"] = {  }, ["inventory"] = {  } }, ["param2"] = 240, ["y"] = 0, ["param1"] = 10, ["z"] = 22, ["name"] = "default:water_source" }, { ["x"] = 0, ["meta"] = { ["fields"] = {  }, ["inventory"] = {  } }, ["param2"] = 240, ["y"] = 0, ["param1"] = 10, ["z"] = 23, ["name"] = "default:water_source" }, { ["x"] = 0, ["meta"] = { ["fields"] = {  }, ["inventory"] = {  } }, ["param2"] = 240, ["y"] = 0, ["param1"] = 10, ["z"] = 24, ["name"] = "default:water_source" }, { ["x"] = 0, ["meta"] = { ["fields"] = {  }, ["inventory"] = {  } }, ["param2"] = 240, ["y"] = 0, ["param1"] = 10, ["z"] = 25, ["name"] = "default:water_source" }, { ["x"] = 0, ["meta"] = { ["fields"] = {  }, ["inventory"] = {  } }, ["param2"] = 240, ["y"] = 0, ["param1"] = 10, ["z"] = 26, ["name"] = "default:water_source" }, { ["x"] = 0, ["meta"] = { ["fields"] = {  }, ["inventory"] = {  } }, ["param2"] = 240, ["y"] = 0, ["param1"] = 10, ["z"] = 27, ["name"] = "default:water_source" }, { ["x"] = 0, ["meta"] = { ["fields"] = {  }, ["inventory"] = {  } }, ["param2"] = 240, ["y"] = 0, ["param1"] = 10, ["z"] = 28, ["name"] = "default:water_source" }, { ["x"] = 0, ["meta"] = { ["fields"] = {  }, ["inventory"] = {  } }, ["param2"] = 240, ["y"] = 0, ["param1"] = 10, ["z"] = 29, ["name"] = "default:water_source" }, { ["x"] = 0, ["meta"] = { ["fields"] = {  }, ["inventory"] = {  } }, ["param2"] = 240, ["y"] = 0, ["param1"] = 10, ["z"] = 30, ["name"] = "default:water_source" }, { ["x"] = 0, ["meta"] = { ["fields"] = {  }, ["inventory"] = {  } }, ["param2"] = 240, ["y"] = 0, ["param1"] = 10, ["z"] = 31, ["name"] = "default:water_source" }, { ["x"] = 0, ["meta"] = { ["fields"] = {  }, ["inventory"] = {  } }, ["param2"] = 240, ["y"] = 0, ["param1"] = 10, ["z"] = 32, ["name"] = "default:water_source" }, { ["x"] = 0, ["meta"] = { ["fields"] = {  }, ["inventory"] = {  } }, ["param2"] = 240, ["y"] = 0, ["param1"] = 10, ["z"] = 33, ["name"] = "default:water_source" }, { ["x"] = 0, ["meta"] = { ["fields"] = {  }, ["inventory"] = {  } }, ["param2"] = 240, ["y"] = 0, ["param1"] = 10, ["z"] = 34, ["name"] = "default:water_source" }, { ["x"] = 0, ["meta"] = { ["fields"] = {  }, ["inventory"] = {  } }, ["param2"] = 0, ["y"] = 0, ["param1"] = 10, ["z"] = 35, ["name"] = "default:water_source" }, { ["x"] = 0, ["meta"] = { ["fields"] = {  }, ["inventory"] = {  } }, ["param2"] = 0, ["y"] = 0, ["param1"] = 10, ["z"] = 36, ["name"] = "default:water_source" }, { ["x"] = 0, ["meta"] = { ["fields"] = {  }, ["inventory"] = {  } }, ["param2"] = 0, ["y"] = 0, ["param1"] = 10, ["z"] = 37, ["name"] = "default:water_source" }, { ["x"] = 0, ["meta"] = { ["fields"] = {  }, ["inventory"] = {  } }, ["param2"] = 0, ["y"] = 0, ["param1"] = 10, ["z"] = 38, ["name"] = "default:water_source" }, { ["x"] = 0, ["meta"] = { ["fields"] = {  }, ["inventory"] = {  } }, ["param2"] = 0, ["y"] = 0, ["param1"] = 10, ["z"] = 39, ["name"] = "default:water_source" }, { ["x"] = 0, ["meta"] = { ["fields"] = {  }, ["inventory"] = {  } }, ["param2"] = 0, ["y"] = 0, ["param1"] = 10, ["z"] = 40, ["name"] = "default:water_source" }, { ["x"] = 0, ["meta"] = { ["fields"] = {  }, ["inventory"] = {  } }, ["param2"] = 0, ["y"] = 0, ["param1"] = 10, ["z"] = 41, ["name"] = "default:water_source" }, { ["x"] = 0, ["meta"] = { ["fields"] = {  }, ["inventory"] = {  } }, ["param2"] = 0, ["y"] = 1, ["param1"] = 11, ["z"] = 0, ["name"] = "default:water_source" }, { ["x"] = 0, ["meta"] = { ["fields"] = {  }, ["inventory"] = {  } }, ["param2"] = 0, ["y"] = 1, ["param1"] = 11, ["z"] = 1, ["name"] = "default:water_source" }, { ["x"] = 0, ["meta"] = { ["fields"] = {  }, ["inventory"] = {  } }, ["param2"] = 0, ["y"] = 1, ["param1"] = 11, ["z"] = 2, ["name"] = "default:water_source" }, { ["x"] = 0, ["meta"] = { ["fields"] = {  }, ["inventory"] = {  } }, ["param2"] = 0, ["y"] = 1, ["param1"] = 11, ["z"] = 3, ["name"] = "default:water_source" }, { ["x"] = 0, ["meta"] = { ["fields"] = {  }, ["inventory"] = {  } }, ["param2"] = 0, ["y"] = 1, ["param1"] = 11, ["z"] = 4, ["name"] = "default:water_source" }, { ["x"] = 0, ["meta"] = { ["fields"] = {  }, ["inventory"] = {  } }, ["param2"] = 0, ["y"] = 1, ["param1"] = 11, ["z"] = 5, ["name"] = "default:water_source" }, { ["x"] = 0, ["meta"] = { ["fields"] = {  }, ["inventory"] = {  } }, ["param2"] = 0, ["y"] = 1, ["param1"] = 11, ["z"] = 6, ["name"] = "default:water_source" }, { ["x"] = 0, ["meta"] = { ["fields"] = {  }, ["inventory"] = {  } }, ["param2"] = 240, ["y"] = 1, ["param1"] = 11, ["z"] = 7, ["name"] = "default:water_source" }, { ["x"] = 0, ["meta"] = { ["fields"] = {  }, ["inventory"] = {  } }, ["param2"] = 240, ["y"] = 1, ["param1"] = 11, ["z"] = 8, ["name"] = "default:water_source" }, { ["x"] = 0, ["meta"] = { ["fields"] = {  }, ["inventory"] = {  } }, ["param2"] = 240, ["y"] = 1, ["param1"] = 11, ["z"] = 9, ["name"] = "default:water_source" }, { ["x"] = 0, ["meta"] = { ["fields"] = {  }, ["inventory"] = {  } }, ["param2"] = 240, ["y"] = 1, ["param1"] = 11, ["z"] = 10, ["name"] = "default:water_source" }, { ["x"] = 0, ["meta"] = { ["fields"] = {  }, ["inventory"] = {  } }, ["param2"] = 240, ["y"] = 1, ["param1"] = 11, ["z"] = 11, ["name"] = "default:water_source" }, { ["x"] = 0, ["meta"] = { ["fields"] = {  }, ["inventory"] = {  } }, ["param2"] = 240, ["y"] = 1, ["param1"] = 11, ["z"] = 12, ["name"] = "default:water_source" }, { ["x"] = 0, ["meta"] = { ["fields"] = {  }, ["inventory"] = {  } }, ["param2"] = 240, ["y"] = 1, ["param1"] = 11, ["z"] = 13, ["name"] = "default:water_source" }, { ["x"] = 0, ["meta"] = { ["fields"] = {  }, ["inventory"] = {  } }, ["param2"] = 240, ["y"] = 1, ["param1"] = 11, ["z"] = 14, ["name"] = "default:water_source" }, { ["x"] = 0, ["meta"] = { ["fields"] = {  }, ["inventory"] = {  } }, ["param2"] = 240, ["y"] = 1, ["param1"] = 11, ["z"] = 15, ["name"] = "default:water_source" }, { ["x"] = 0, ["meta"] = { ["fields"] = {  }, ["inventory"] = {  } }, ["param2"] = 240, ["y"] = 1, ["param1"] = 11, ["z"] = 16, ["name"] = "default:water_source" }, { ["x"] = 0, ["meta"] = { ["fields"] = {  }, ["inventory"] = {  } }, ["param2"] = 240, ["y"] = 1, ["param1"] = 11, ["z"] = 17, ["name"] = "default:water_source" }, { ["x"] = 0, ["meta"] = { ["fields"] = {  }, ["inventory"] = {  } }, ["param2"] = 240, ["y"] = 1, ["param1"] = 11, ["z"] = 18, ["name"] = "default:water_source" }, { ["x"] = 0, ["meta"] = { ["fields"] = {  }, ["inventory"] = {  } }, ["param2"] = 240, ["y"] = 1, ["param1"] = 11, ["z"] = 19, ["name"] = "default:water_source" }, { ["x"] = 0, ["meta"] = { ["fields"] = {  }, ["inventory"] = {  } }, ["param2"] = 240, ["y"] = 1, ["param1"] = 11, ["z"] = 20, ["name"] = "default:water_source" }, { ["x"] = 0, ["meta"] = { ["fields"] = {  }, ["inventory"] = {  } }, ["param2"] = 240, ["y"] = 1, ["param1"] = 11, ["z"] = 21, ["name"] = "default:water_source" }, { ["x"] = 0, ["meta"] = { ["fields"] = {  }, ["inventory"] = {  } }, ["param2"] = 240, ["y"] = 1, ["param1"] = 11, ["z"] = 22, ["name"] = "default:water_source" }, { ["x"] = 0, ["meta"] = { ["fields"] = {  }, ["inventory"] = {  } }, ["param2"] = 240, ["y"] = 1, ["param1"] = 11, ["z"] = 23, ["name"] = "default:water_source" }, { ["x"] = 0, ["meta"] = { ["fields"] = {  }, ["inventory"] = {  } }, ["param2"] = 240, ["y"] = 1, ["param1"] = 11, ["z"] = 24, ["name"] = "default:water_source" }, { ["x"] = 0, ["meta"] = { ["fields"] = {  }, ["inventory"] = {  } }, ["param2"] = 240, ["y"] = 1, ["param1"] = 11, ["z"] = 25, ["name"] = "default:water_source" }, { ["x"] = 0, ["meta"] = { ["fields"] = {  }, ["inventory"] = {  } }, ["param2"] = 240, ["y"] = 1, ["param1"] = 11, ["z"] = 26, ["name"] = "default:water_source" }, { ["x"] = 0, ["meta"] = { ["fields"] = {  }, ["inventory"] = {  } }, ["param2"] = 240, ["y"] = 1, ["param1"] = 11, ["z"] = 27, ["name"] = "default:water_source" }, { ["x"] = 0, ["meta"] = { ["fields"] = {  }, ["inventory"] = {  } }, ["param2"] = 240, ["y"] = 1, ["param1"] = 11, ["z"] = 28, ["name"] = "default:water_source" }, { ["x"] = 0, ["meta"] = { ["fields"] = {  }, ["inventory"] = {  } }, ["param2"] = 240, ["y"] = 1, ["param1"] = 11, ["z"] = 29, ["name"] = "default:water_source" }, { ["x"] = 0, ["meta"] = { ["fields"] = {  }, ["inventory"] = {  } }, ["param2"] = 240, ["y"] = 1, ["param1"] = 11, ["z"] = 30, ["name"] = "default:water_source" }, { ["x"] = 0, ["meta"] = { ["fields"] = {  }, ["inventory"] = {  } }, ["param2"] = 240, ["y"] = 1, ["param1"] = 11, ["z"] = 31, ["name"] = "default:water_source" }, { ["x"] = 0, ["meta"] = { ["fields"] = {  }, ["inventory"] = {  } }, ["param2"] = 240, ["y"] = 1, ["param1"] = 11, ["z"] = 32, ["name"] = "default:water_source" }, { ["x"] = 0, ["meta"] = { ["fields"] = {  }, ["inventory"] = {  } }, ["param2"] = 240, ["y"] = 1, ["param1"] = 11, ["z"] = 33, ["name"] = "default:water_source" }, { ["x"] = 0, ["meta"] = { ["fields"] = {  }, ["inventory"] = {  } }, ["param2"] = 240, ["y"] = 1, ["param1"] = 11, ["z"] = 34, ["name"] = "default:water_source" }, { ["x"] = 0, ["meta"] = { ["fields"] = {  }, ["inventory"] = {  } }, ["param2"] = 0, ["y"] = 1, ["param1"] = 11, ["z"] = 35, ["name"] = "default:water_source" }, { ["x"] = 0, ["meta"] = { ["fields"] = {  }, ["inventory"] = {  } }, ["param2"] = 0, ["y"] = 1, ["param1"] = 11, ["z"] = 36, ["name"] = "default:water_source" }, { ["x"] = 0, ["meta"] = { ["fields"] = {  }, ["inventory"] = {  } }, ["param2"] = 0, ["y"] = 1, ["param1"] = 11, ["z"] = 37, ["name"] = "default:water_source" }, { ["x"] = 0, ["meta"] = { ["fields"] = {  }, ["inventory"] = {  } }, ["param2"] = 0, ["y"] = 1, ["param1"] = 11, ["z"] = 38, ["name"] = "default:water_source" }, { ["x"] = 0, ["meta"] = { ["fields"] = {  }, ["inventory"] = {  } }, ["param2"] = 0, ["y"] = 1, ["param1"] = 11, ["z"] = 39, ["name"] = "default:water_source" }, { ["x"] = 0, ["meta"] = { ["fields"] = {  }, ["inventory"] = {  } }, ["param2"] = 0, ["y"] = 1, ["param1"] = 11, ["z"] = 40, ["name"] = "default:water_source" }, { ["x"] = 0, ["meta"] = { ["fields"] = {  }, ["inventory"] = {  } }, ["param2"] = 0, ["y"] = 1, ["param1"] = 11, ["z"] = 41, ["name"] = "default:water_source" }, { ["x"] = 0, ["meta"] = { ["fields"] = {  }, ["inventory"] = {  } }, ["param2"] = 0, ["y"] = 2, ["param1"] = 12, ["z"] = 0, ["name"] = "default:water_source" }, { ["x"] = 0, ["meta"] = { ["fields"] = {  }, ["inventory"] = {  } }, ["param2"] = 0, ["y"] = 2, ["param1"] = 12, ["z"] = 1, ["name"] = "default:water_source" }, { ["x"] = 0, ["meta"] = { ["fields"] = {  }, ["inventory"] = {  } }, ["param2"] = 0, ["y"] = 2, ["param1"] = 12, ["z"] = 2, ["name"] = "default:water_source" }, { ["x"] = 0, ["meta"] = { ["fields"] = {  }, ["inventory"] = {  } }, ["param2"] = 0, ["y"] = 2, ["param1"] = 12, ["z"] = 3, ["name"] = "default:water_source" }, { ["x"] = 0, ["meta"] = { ["fields"] = {  }, ["inventory"] = {  } }, ["param2"] = 0, ["y"] = 2, ["param1"] = 12, ["z"] = 4, ["name"] = "default:water_source" }, { ["x"] = 0, ["meta"] = { ["fields"] = {  }, ["inventory"] = {  } }, ["param2"] = 0, ["y"] = 2, ["param1"] = 12, ["z"] = 5, ["name"] = "default:water_source" }, { ["x"] = 0, ["meta"] = { ["fields"] = {  }, ["inventory"] = {  } }, ["param2"] = 0, ["y"] = 2, ["param1"] = 12, ["z"] = 6, ["name"] = "default:water_source" }, { ["x"] = 0, ["meta"] = { ["fields"] = {  }, ["inventory"] = {  } }, ["param2"] = 0, ["y"] = 2, ["param1"] = 12, ["z"] = 7, ["name"] = "default:water_source" }, { ["x"] = 0, ["meta"] = { ["fields"] = {  }, ["inventory"] = {  } }, ["param2"] = 0, ["y"] = 2, ["param1"] = 12, ["z"] = 8, ["name"] = "default:water_source" }, { ["x"] = 0, ["meta"] = { ["fields"] = {  }, ["inventory"] = {  } }, ["param2"] = 0, ["y"] = 2, ["param1"] = 12, ["z"] = 9, ["name"] = "default:water_source" }, { ["x"] = 0, ["meta"] = { ["fields"] = {  }, ["inventory"] = {  } }, ["param2"] = 0, ["y"] = 2, ["param1"] = 12, ["z"] = 10, ["name"] = "default:water_source" }, { ["x"] = 0, ["meta"] = { ["fields"] = {  }, ["inventory"] = {  } }, ["param2"] = 0, ["y"] = 2, ["param1"] = 12, ["z"] = 11, ["name"] = "default:water_source" }, { ["x"] = 0, ["meta"] = { ["fields"] = {  }, ["inventory"] = {  } }, ["param2"] = 0, ["y"] = 2, ["param1"] = 12, ["z"] = 12, ["name"] = "default:water_source" }, { ["x"] = 0, ["meta"] = { ["fields"] = {  }, ["inventory"] = {  } }, ["param2"] = 0, ["y"] = 2, ["param1"] = 12, ["z"] = 13, ["name"] = "default:water_source" }, { ["x"] = 0, ["meta"] = { ["fields"] = {  }, ["inventory"] = {  } }, ["param2"] = 0, ["y"] = 2, ["param1"] = 12, ["z"] = 14, ["name"] = "default:water_source" }, { ["x"] = 0, ["meta"] = { ["fields"] = {  }, ["inventory"] = {  } }, ["param2"] = 0, ["y"] = 2, ["param1"] = 12, ["z"] = 15, ["name"] = "default:water_source" }, { ["x"] = 0, ["meta"] = { ["fields"] = {  }, ["inventory"] = {  } }, ["param2"] = 0, ["y"] = 2, ["param1"] = 12, ["z"] = 16, ["name"] = "default:water_source" }, { ["x"] = 0, ["meta"] = { ["fields"] = {  }, ["inventory"] = {  } }, ["param2"] = 0, ["y"] = 2, ["param1"] = 12, ["z"] = 17, ["name"] = "default:water_source" }, { ["x"] = 0, ["meta"] = { ["fields"] = {  }, ["inventory"] = {  } }, ["param2"] = 0, ["y"] = 2, ["param1"] = 12, ["z"] = 18, ["name"] = "default:water_source" }, { ["x"] = 0, ["meta"] = { ["fields"] = {  }, ["inventory"] = {  } }, ["param2"] = 0, ["y"] = 2, ["param1"] = 12, ["z"] = 19, ["name"] = "default:water_source" }, { ["x"] = 0, ["meta"] = { ["fields"] = {  }, ["inventory"] = {  } }, ["param2"] = 0, ["y"] = 2, ["param1"] = 12, ["z"] = 20, ["name"] = "default:water_source" }, { ["x"] = 0, ["meta"] = { ["fields"] = {  }, ["inventory"] = {  } }, ["param2"] = 0, ["y"] = 2, ["param1"] = 12, ["z"] = 21, ["name"] = "default:water_source" }, { ["x"] = 0, ["meta"] = { ["fields"] = {  }, ["inventory"] = {  } }, ["param2"] = 0, ["y"] = 2, ["param1"] = 12, ["z"] = 22, ["name"] = "default:water_source" }, { ["x"] = 0, ["meta"] = { ["fields"] = {  }, ["inventory"] = {  } }, ["param2"] = 0, ["y"] = 2, ["param1"] = 12, ["z"] = 23, ["name"] = "default:water_source" }, { ["x"] = 0, ["meta"] = { ["fields"] = {  }, ["inventory"] = {  } }, ["param2"] = 0, ["y"] = 2, ["param1"] = 12, ["z"] = 24, ["name"] = "default:water_source" }, { ["x"] = 0, ["meta"] = { ["fields"] = {  }, ["inventory"] = {  } }, ["param2"] = 0, ["y"] = 2, ["param1"] = 12, ["z"] = 25, ["name"] = "default:water_source" }, { ["x"] = 0, ["meta"] = { ["fields"] = {  }, ["inventory"] = {  } }, ["param2"] = 0, ["y"] = 2, ["param1"] = 12, ["z"] = 26, ["name"] = "default:water_source" }, { ["x"] = 0, ["meta"] = { ["fields"] = {  }, ["inventory"] = {  } }, ["param2"] = 0, ["y"] = 2, ["param1"] = 12, ["z"] = 27, ["name"] = "default:water_source" }, { ["x"] = 0, ["meta"] = { ["fields"] = {  }, ["inventory"] = {  } }, ["param2"] = 0, ["y"] = 2, ["param1"] = 12, ["z"] = 28, ["name"] = "default:water_source" }, { ["x"] = 0, ["meta"] = { ["fields"] = {  }, ["inventory"] = {  } }, ["param2"] = 0, ["y"] = 2, ["param1"] = 12, ["z"] = 29, ["name"] = "default:water_source" }, { ["x"] = 0, ["meta"] = { ["fields"] = {  }, ["inventory"] = {  } }, ["param2"] = 0, ["y"] = 2, ["param1"] = 12, ["z"] = 30, ["name"] = "default:water_source" }, { ["x"] = 0, ["meta"] = { ["fields"] = {  }, ["inventory"] = {  } }, ["param2"] = 0, ["y"] = 2, ["param1"] = 12, ["z"] = 31, ["name"] = "default:water_source" }, { ["x"] = 0, ["meta"] = { ["fields"] = {  }, ["inventory"] = {  } }, ["param2"] = 0, ["y"] = 2, ["param1"] = 12, ["z"] = 32, ["name"] = "default:water_source" }, { ["x"] = 0, ["meta"] = { ["fields"] = {  }, ["inventory"] = {  } }, ["param2"] = 0, ["y"] = 2, ["param1"] = 12, ["z"] = 33, ["name"] = "default:water_source" }, { ["x"] = 0, ["meta"] = { ["fields"] = {  }, ["inventory"] = {  } }, ["param2"] = 0, ["y"] = 2, ["param1"] = 12, ["z"] = 34, ["name"] = "default:water_source" }, { ["x"] = 0, ["meta"] = { ["fields"] = {  }, ["inventory"] = {  } }, ["param2"] = 0, ["y"] = 2, ["param1"] = 12, ["z"] = 35, ["name"] = "default:water_source" }, { ["x"] = 0, ["meta"] = { ["fields"] = {  }, ["inventory"] = {  } }, ["param2"] = 0, ["y"] = 2, ["param1"] = 12, ["z"] = 36, ["name"] = "default:water_source" }, { ["x"] = 0, ["meta"] = { ["fields"] = {  }, ["inventory"] = {  } }, ["param2"] = 0, ["y"] = 2, ["param1"] = 12, ["z"] = 37, ["name"] = "default:water_source" }, { ["x"] = 0, ["meta"] = { ["fields"] = {  }, ["inventory"] = {  } }, ["param2"] = 0, ["y"] = 2, ["param1"] = 12, ["z"] = 38, ["name"] = "default:water_source" }, { ["x"] = 0, ["meta"] = { ["fields"] = {  }, ["inventory"] = {  } }, ["param2"] = 0, ["y"] = 2, ["param1"] = 12, ["z"] = 39, ["name"] = "default:water_source" }, { ["x"] = 0, ["meta"] = { ["fields"] = {  }, ["inventory"] = {  } }, ["param2"] = 0, ["y"] = 2, ["param1"] = 12, ["z"] = 40, ["name"] = "default:water_source" }, { ["x"] = 0, ["meta"] = { ["fields"] = {  }, ["inventory"] = {  } }, ["param2"] = 0, ["y"] = 2, ["param1"] = 12, ["z"] = 41, ["name"] = "default:water_source" }, { ["x"] = 0, ["meta"] = { ["fields"] = {  }, ["inventory"] = {  } }, ["param2"] = 0, ["y"] = 3, ["param1"] = 13, ["z"] = 0, ["name"] = "default:water_source" }, { ["x"] = 0, ["meta"] = { ["fields"] = {  }, ["inventory"] = {  } }, ["param2"] = 0, ["y"] = 3, ["param1"] = 13, ["z"] = 1, ["name"] = "default:water_source" }, { ["x"] = 0, ["meta"] = { ["fields"] = {  }, ["inventory"] = {  } }, ["param2"] = 0, ["y"] = 3, ["param1"] = 13, ["z"] = 2, ["name"] = "default:water_source" }, { ["x"] = 0, ["meta"] = { ["fields"] = {  }, ["inventory"] = {  } }, ["param2"] = 0, ["y"] = 3, ["param1"] = 13, ["z"] = 3, ["name"] = "default:water_source" }, { ["x"] = 0, ["meta"] = { ["fields"] = {  }, ["inventory"] = {  } }, ["param2"] = 0, ["y"] = 3, ["param1"] = 13, ["z"] = 4, ["name"] = "default:water_source" }, { ["x"] = 0, ["meta"] = { ["fields"] = {  }, ["inventory"] = {  } }, ["param2"] = 0, ["y"] = 3, ["param1"] = 13, ["z"] = 5, ["name"] = "default:water_source" }, { ["x"] = 0, ["meta"] = { ["fields"] = {  }, ["inventory"] = {  } }, ["param2"] = 0, ["y"] = 3, ["param1"] = 13, ["z"] = 6, ["name"] = "default:water_source" }, { ["x"] = 0, ["meta"] = { ["fields"] = {  }, ["inventory"] = {  } }, ["param2"] = 0, ["y"] = 3, ["param1"] = 13, ["z"] = 7, ["name"] = "default:water_source" }, { ["x"] = 0, ["meta"] = { ["fields"] = {  }, ["inventory"] = {  } }, ["param2"] = 0, ["y"] = 3, ["param1"] = 13, ["z"] = 8, ["name"] = "default:water_source" }, { ["x"] = 0, ["meta"] = { ["fields"] = {  }, ["inventory"] = {  } }, ["param2"] = 0, ["y"] = 3, ["param1"] = 13, ["z"] = 9, ["name"] = "default:water_source" }, { ["x"] = 0, ["meta"] = { ["fields"] = {  }, ["inventory"] = {  } }, ["param2"] = 0, ["y"] = 3, ["param1"] = 13, ["z"] = 10, ["name"] = "default:water_source" }, { ["x"] = 0, ["meta"] = { ["fields"] = {  }, ["inventory"] = {  } }, ["param2"] = 0, ["y"] = 3, ["param1"] = 13, ["z"] = 11, ["name"] = "default:water_source" }, { ["x"] = 0, ["meta"] = { ["fields"] = {  }, ["inventory"] = {  } }, ["param2"] = 0, ["y"] = 3, ["param1"] = 13, ["z"] = 12, ["name"] = "default:water_source" }, { ["x"] = 0, ["meta"] = { ["fields"] = {  }, ["inventory"] = {  } }, ["param2"] = 0, ["y"] = 3, ["param1"] = 13, ["z"] = 13, ["name"] = "default:water_source" }, { ["x"] = 0, ["meta"] = { ["fields"] = {  }, ["inventory"] = {  } }, ["param2"] = 0, ["y"] = 3, ["param1"] = 13, ["z"] = 14, ["name"] = "default:water_source" }, { ["x"] = 0, ["meta"] = { ["fields"] = {  }, ["inventory"] = {  } }, ["param2"] = 0, ["y"] = 3, ["param1"] = 13, ["z"] = 15, ["name"] = "default:water_source" }, { ["x"] = 0, ["meta"] = { ["fields"] = {  }, ["inventory"] = {  } }, ["param2"] = 0, ["y"] = 3, ["param1"] = 13, ["z"] = 16, ["name"] = "default:water_source" }, { ["x"] = 0, ["meta"] = { ["fields"] = {  }, ["inventory"] = {  } }, ["param2"] = 0, ["y"] = 3, ["param1"] = 13, ["z"] = 17, ["name"] = "default:water_source" }, { ["x"] = 0, ["meta"] = { ["fields"] = {  }, ["inventory"] = {  } }, ["param2"] = 0, ["y"] = 3, ["param1"] = 13, ["z"] = 18, ["name"] = "default:water_source" }, { ["x"] = 0, ["meta"] = { ["fields"] = {  }, ["inventory"] = {  } }, ["param2"] = 0, ["y"] = 3, ["param1"] = 13, ["z"] = 19, ["name"] = "default:water_source" }, { ["x"] = 0, ["meta"] = { ["fields"] = {  }, ["inventory"] = {  } }, ["param2"] = 0, ["y"] = 3, ["param1"] = 13, ["z"] = 20, ["name"] = "default:water_source" }, { ["x"] = 0, ["meta"] = { ["fields"] = {  }, ["inventory"] = {  } }, ["param2"] = 0, ["y"] = 3, ["param1"] = 13, ["z"] = 21, ["name"] = "default:water_source" }, { ["x"] = 0, ["meta"] = { ["fields"] = {  }, ["inventory"] = {  } }, ["param2"] = 0, ["y"] = 3, ["param1"] = 13, ["z"] = 22, ["name"] = "default:water_source" }, { ["x"] = 0, ["meta"] = { ["fields"] = {  }, ["inventory"] = {  } }, ["param2"] = 0, ["y"] = 3, ["param1"] = 13, ["z"] = 23, ["name"] = "default:water_source" }, { ["x"] = 0, ["meta"] = { ["fields"] = {  }, ["inventory"] = {  } }, ["param2"] = 0, ["y"] = 3, ["param1"] = 13, ["z"] = 24, ["name"] = "default:water_source" }, { ["x"] = 0, ["meta"] = { ["fields"] = {  }, ["inventory"] = {  } }, ["param2"] = 0, ["y"] = 3, ["param1"] = 13, ["z"] = 25, ["name"] = "default:water_source" }, { ["x"] = 0, ["meta"] = { ["fields"] = {  }, ["inventory"] = {  } }, ["param2"] = 0, ["y"] = 3, ["param1"] = 13, ["z"] = 26, ["name"] = "default:water_source" }, { ["x"] = 0, ["meta"] = { ["fields"] = {  }, ["inventory"] = {  } }, ["param2"] = 0, ["y"] = 3, ["param1"] = 13, ["z"] = 27, ["name"] = "default:water_source" }, { ["x"] = 0, ["meta"] = { ["fields"] = {  }, ["inventory"] = {  } }, ["param2"] = 0, ["y"] = 3, ["param1"] = 13, ["z"] = 28, ["name"] = "default:water_source" }, { ["x"] = 0, ["meta"] = { ["fields"] = {  }, ["inventory"] = {  } }, ["param2"] = 0, ["y"] = 3, ["param1"] = 13, ["z"] = 29, ["name"] = "default:water_source" }, { ["x"] = 0, ["meta"] = { ["fields"] = {  }, ["inventory"] = {  } }, ["param2"] = 0, ["y"] = 3, ["param1"] = 13, ["z"] = 30, ["name"] = "default:water_source" }, { ["x"] = 0, ["meta"] = { ["fields"] = {  }, ["inventory"] = {  } }, ["param2"] = 0, ["y"] = 3, ["param1"] = 13, ["z"] = 31, ["name"] = "default:water_source" }, { ["x"] = 0, ["meta"] = { ["fields"] = {  }, ["inventory"] = {  } }, ["param2"] = 0, ["y"] = 3, ["param1"] = 13, ["z"] = 32, ["name"] = "default:water_source" }, { ["x"] = 0, ["meta"] = { ["fields"] = {  }, ["inventory"] = {  } }, ["param2"] = 0, ["y"] = 3, ["param1"] = 13, ["z"] = 33, ["name"] = "default:water_source" }, { ["x"] = 0, ["meta"] = { ["fields"] = {  }, ["inventory"] = {  } }, ["param2"] = 0, ["y"] = 3, ["param1"] = 13, ["z"] = 34, ["name"] = "default:water_source" }, { ["x"] = 0, ["meta"] = { ["fields"] = {  }, ["inventory"] = {  } }, ["param2"] = 0, ["y"] = 3, ["param1"] = 13, ["z"] = 35, ["name"] = "default:water_source" }, { ["x"] = 0, ["meta"] = { ["fields"] = {  }, ["inventory"] = {  } }, ["param2"] = 0, ["y"] = 3, ["param1"] = 13, ["z"] = 36, ["name"] = "default:water_source" }, { ["x"] = 0, ["meta"] = { ["fields"] = {  }, ["inventory"] = {  } }, ["param2"] = 0, ["y"] = 3, ["param1"] = 13, ["z"] = 37, ["name"] = "default:water_source" }, { ["x"] = 0, ["meta"] = { ["fields"] = {  }, ["inventory"] = {  } }, ["param2"] = 0, ["y"] = 3, ["param1"] = 13, ["z"] = 38, ["name"] = "default:water_source" }, { ["x"] = 0, ["meta"] = { ["fields"] = {  }, ["inventory"] = {  } }, ["param2"] = 0, ["y"] = 3, ["param1"] = 13, ["z"] = 39, ["name"] = "default:water_source" }, { ["x"] = 0, ["meta"] = { ["fields"] = {  }, ["inventory"] = {  } }, ["param2"] = 0, ["y"] = 3, ["param1"] = 13, ["z"] = 40, ["name"] = "default:water_source" }, { ["x"] = 0, ["meta"] = { ["fields"] = {  }, ["inventory"] = {  } }, ["param2"] = 0, ["y"] = 3, ["param1"] = 13, ["z"] = 41, ["name"] = "default:water_source" }, { ["x"] = 1, ["meta"] = { ["fields"] = {  }, ["inventory"] = {  } }, ["param2"] = 0, ["y"] = 0, ["param1"] = 10, ["z"] = 0, ["name"] = "default:water_source" }, { ["x"] = 1, ["meta"] = { ["fields"] = {  }, ["inventory"] = {  } }, ["param2"] = 0, ["y"] = 0, ["param1"] = 10, ["z"] = 1, ["name"] = "default:water_source" }, { ["x"] = 1, ["meta"] = { ["fields"] = {  }, ["inventory"] = {  } }, ["param2"] = 0, ["y"] = 0, ["param1"] = 10, ["z"] = 2, ["name"] = "default:water_source" }, { ["x"] = 1, ["meta"] = { ["fields"] = {  }, ["inventory"] = {  } }, ["param2"] = 0, ["y"] = 0, ["param1"] = 10, ["z"] = 3, ["name"] = "default:water_source" }, { ["x"] = 1, ["meta"] = { ["fields"] = {  }, ["inventory"] = {  } }, ["param2"] = 0, ["y"] = 0, ["param1"] = 10, ["z"] = 4, ["name"] = "default:water_source" }, { ["x"] = 1, ["meta"] = { ["fields"] = {  }, ["inventory"] = {  } }, ["param2"] = 0, ["y"] = 0, ["param1"] = 10, ["z"] = 5, ["name"] = "default:water_source" }, { ["x"] = 1, ["meta"] = { ["fields"] = {  }, ["inventory"] = {  } }, ["param2"] = 0, ["y"] = 0, ["param1"] = 10, ["z"] = 6, ["name"] = "default:water_source" }, { ["x"] = 1, ["meta"] = { ["fields"] = {  }, ["inventory"] = {  } }, ["param2"] = 240, ["y"] = 0, ["param1"] = 10, ["z"] = 7, ["name"] = "default:water_source" }, { ["x"] = 1, ["meta"] = { ["fields"] = {  }, ["inventory"] = {  } }, ["param2"] = 240, ["y"] = 0, ["param1"] = 10, ["z"] = 8, ["name"] = "default:water_source" }, { ["x"] = 1, ["meta"] = { ["fields"] = {  }, ["inventory"] = {  } }, ["param2"] = 240, ["y"] = 0, ["param1"] = 10, ["z"] = 9, ["name"] = "default:water_source" }, { ["x"] = 1, ["meta"] = { ["fields"] = {  }, ["inventory"] = {  } }, ["param2"] = 240, ["y"] = 0, ["param1"] = 10, ["z"] = 10, ["name"] = "default:water_source" }, { ["x"] = 1, ["meta"] = { ["fields"] = {  }, ["inventory"] = {  } }, ["param2"] = 240, ["y"] = 0, ["param1"] = 10, ["z"] = 11, ["name"] = "default:water_source" }, { ["x"] = 1, ["meta"] = { ["fields"] = {  }, ["inventory"] = {  } }, ["param2"] = 240, ["y"] = 0, ["param1"] = 10, ["z"] = 12, ["name"] = "default:water_source" }, { ["x"] = 1, ["meta"] = { ["fields"] = {  }, ["inventory"] = {  } }, ["param2"] = 240, ["y"] = 0, ["param1"] = 10, ["z"] = 13, ["name"] = "default:water_source" }, { ["x"] = 1, ["meta"] = { ["fields"] = {  }, ["inventory"] = {  } }, ["param2"] = 240, ["y"] = 0, ["param1"] = 10, ["z"] = 14, ["name"] = "default:water_source" }, { ["x"] = 1, ["meta"] = { ["fields"] = {  }, ["inventory"] = {  } }, ["param2"] = 240, ["y"] = 0, ["param1"] = 10, ["z"] = 15, ["name"] = "default:water_source" }, { ["x"] = 1, ["meta"] = { ["fields"] = {  }, ["inventory"] = {  } }, ["param2"] = 240, ["y"] = 0, ["param1"] = 10, ["z"] = 16, ["name"] = "default:water_source" }, { ["x"] = 1, ["meta"] = { ["fields"] = {  }, ["inventory"] = {  } }, ["param2"] = 240, ["y"] = 0, ["param1"] = 10, ["z"] = 17, ["name"] = "default:water_source" }, { ["x"] = 1, ["meta"] = { ["fields"] = {  }, ["inventory"] = {  } }, ["param2"] = 240, ["y"] = 0, ["param1"] = 10, ["z"] = 18, ["name"] = "default:water_source" }, { ["x"] = 1, ["meta"] = { ["fields"] = {  }, ["inventory"] = {  } }, ["param2"] = 240, ["y"] = 0, ["param1"] = 10, ["z"] = 19, ["name"] = "default:water_source" }, { ["x"] = 1, ["meta"] = { ["fields"] = {  }, ["inventory"] = {  } }, ["param2"] = 240, ["y"] = 0, ["param1"] = 10, ["z"] = 20, ["name"] = "default:water_source" }, { ["x"] = 1, ["meta"] = { ["fields"] = {  }, ["inventory"] = {  } }, ["param2"] = 240, ["y"] = 0, ["param1"] = 10, ["z"] = 21, ["name"] = "default:water_source" }, { ["x"] = 1, ["meta"] = { ["fields"] = {  }, ["inventory"] = {  } }, ["param2"] = 240, ["y"] = 0, ["param1"] = 10, ["z"] = 22, ["name"] = "default:water_source" }, { ["x"] = 1, ["meta"] = { ["fields"] = {  }, ["inventory"] = {  } }, ["param2"] = 240, ["y"] = 0, ["param1"] = 10, ["z"] = 23, ["name"] = "default:water_source" }, { ["x"] = 1, ["meta"] = { ["fields"] = {  }, ["inventory"] = {  } }, ["param2"] = 240, ["y"] = 0, ["param1"] = 10, ["z"] = 24, ["name"] = "default:water_source" }, { ["x"] = 1, ["meta"] = { ["fields"] = {  }, ["inventory"] = {  } }, ["param2"] = 240, ["y"] = 0, ["param1"] = 10, ["z"] = 25, ["name"] = "default:water_source" }, { ["x"] = 1, ["meta"] = { ["fields"] = {  }, ["inventory"] = {  } }, ["param2"] = 240, ["y"] = 0, ["param1"] = 10, ["z"] = 26, ["name"] = "default:water_source" }, { ["x"] = 1, ["meta"] = { ["fields"] = {  }, ["inventory"] = {  } }, ["param2"] = 240, ["y"] = 0, ["param1"] = 10, ["z"] = 27, ["name"] = "default:water_source" }, { ["x"] = 1, ["meta"] = { ["fields"] = {  }, ["inventory"] = {  } }, ["param2"] = 240, ["y"] = 0, ["param1"] = 10, ["z"] = 28, ["name"] = "default:water_source" }, { ["x"] = 1, ["meta"] = { ["fields"] = {  }, ["inventory"] = {  } }, ["param2"] = 240, ["y"] = 0, ["param1"] = 10, ["z"] = 29, ["name"] = "default:water_source" }, { ["x"] = 1, ["meta"] = { ["fields"] = {  }, ["inventory"] = {  } }, ["param2"] = 240, ["y"] = 0, ["param1"] = 10, ["z"] = 30, ["name"] = "default:water_source" }, { ["x"] = 1, ["meta"] = { ["fields"] = {  }, ["inventory"] = {  } }, ["param2"] = 240, ["y"] = 0, ["param1"] = 10, ["z"] = 31, ["name"] = "default:water_source" }, { ["x"] = 1, ["meta"] = { ["fields"] = {  }, ["inventory"] = {  } }, ["param2"] = 240, ["y"] = 0, ["param1"] = 10, ["z"] = 32, ["name"] = "default:water_source" }, { ["x"] = 1, ["meta"] = { ["fields"] = {  }, ["inventory"] = {  } }, ["param2"] = 240, ["y"] = 0, ["param1"] = 10, ["z"] = 33, ["name"] = "default:water_source" }, { ["x"] = 1, ["meta"] = { ["fields"] = {  }, ["inventory"] = {  } }, ["param2"] = 240, ["y"] = 0, ["param1"] = 10, ["z"] = 34, ["name"] = "default:water_source" }, { ["x"] = 1, ["meta"] = { ["fields"] = {  }, ["inventory"] = {  } }, ["param2"] = 0, ["y"] = 0, ["param1"] = 10, ["z"] = 35, ["name"] = "default:water_source" }, { ["x"] = 1, ["meta"] = { ["fields"] = {  }, ["inventory"] = {  } }, ["param2"] = 0, ["y"] = 0, ["param1"] = 10, ["z"] = 36, ["name"] = "default:water_source" }, { ["x"] = 1, ["meta"] = { ["fields"] = {  }, ["inventory"] = {  } }, ["param2"] = 0, ["y"] = 0, ["param1"] = 10, ["z"] = 37, ["name"] = "default:water_source" }, { ["x"] = 1, ["meta"] = { ["fields"] = {  }, ["inventory"] = {  } }, ["param2"] = 0, ["y"] = 0, ["param1"] = 10, ["z"] = 38, ["name"] = "default:water_source" }, { ["x"] = 1, ["meta"] = { ["fields"] = {  }, ["inventory"] = {  } }, ["param2"] = 0, ["y"] = 0, ["param1"] = 10, ["z"] = 39, ["name"] = "default:water_source" }, { ["x"] = 1, ["meta"] = { ["fields"] = {  }, ["inventory"] = {  } }, ["param2"] = 0, ["y"] = 0, ["param1"] = 10, ["z"] = 40, ["name"] = "default:water_source" }, { ["x"] = 1, ["meta"] = { ["fields"] = {  }, ["inventory"] = {  } }, ["param2"] = 0, ["y"] = 0, ["param1"] = 10, ["z"] = 41, ["name"] = "default:water_source" }, { ["x"] = 1, ["meta"] = { ["fields"] = {  }, ["inventory"] = {  } }, ["param2"] = 0, ["y"] = 1, ["param1"] = 11, ["z"] = 0, ["name"] = "default:water_source" }, { ["x"] = 1, ["meta"] = { ["fields"] = {  }, ["inventory"] = {  } }, ["param2"] = 0, ["y"] = 1, ["param1"] = 11, ["z"] = 1, ["name"] = "default:water_source" }, { ["x"] = 1, ["meta"] = { ["fields"] = {  }, ["inventory"] = {  } }, ["param2"] = 0, ["y"] = 1, ["param1"] = 11, ["z"] = 2, ["name"] = "default:water_source" }, { ["x"] = 1, ["meta"] = { ["fields"] = {  }, ["inventory"] = {  } }, ["param2"] = 0, ["y"] = 1, ["param1"] = 11, ["z"] = 3, ["name"] = "default:water_source" }, { ["x"] = 1, ["meta"] = { ["fields"] = {  }, ["inventory"] = {  } }, ["param2"] = 0, ["y"] = 1, ["param1"] = 11, ["z"] = 4, ["name"] = "default:water_source" }, { ["x"] = 1, ["meta"] = { ["fields"] = {  }, ["inventory"] = {  } }, ["param2"] = 0, ["y"] = 1, ["param1"] = 11, ["z"] = 5, ["name"] = "default:water_source" }, { ["x"] = 1, ["meta"] = { ["fields"] = {  }, ["inventory"] = {  } }, ["param2"] = 0, ["y"] = 1, ["param1"] = 11, ["z"] = 6, ["name"] = "default:water_source" }, { ["x"] = 1, ["meta"] = { ["fields"] = {  }, ["inventory"] = {  } }, ["param2"] = 240, ["y"] = 1, ["param1"] = 11, ["z"] = 7, ["name"] = "default:water_source" }, { ["x"] = 1, ["meta"] = { ["fields"] = {  }, ["inventory"] = {  } }, ["param2"] = 240, ["y"] = 1, ["param1"] = 11, ["z"] = 8, ["name"] = "default:water_source" }, { ["x"] = 1, ["meta"] = { ["fields"] = {  }, ["inventory"] = {  } }, ["param2"] = 240, ["y"] = 1, ["param1"] = 11, ["z"] = 9, ["name"] = "default:water_source" }, { ["x"] = 1, ["meta"] = { ["fields"] = {  }, ["inventory"] = {  } }, ["param2"] = 240, ["y"] = 1, ["param1"] = 11, ["z"] = 10, ["name"] = "default:water_source" }, { ["x"] = 1, ["meta"] = { ["fields"] = {  }, ["inventory"] = {  } }, ["param2"] = 240, ["y"] = 1, ["param1"] = 11, ["z"] = 11, ["name"] = "default:water_source" }, { ["x"] = 1, ["meta"] = { ["fields"] = {  }, ["inventory"] = {  } }, ["param2"] = 240, ["y"] = 1, ["param1"] = 11, ["z"] = 12, ["name"] = "default:water_source" }, { ["x"] = 1, ["meta"] = { ["fields"] = {  }, ["inventory"] = {  } }, ["param2"] = 240, ["y"] = 1, ["param1"] = 11, ["z"] = 13, ["name"] = "default:water_source" }, { ["x"] = 1, ["meta"] = { ["fields"] = {  }, ["inventory"] = {  } }, ["param2"] = 240, ["y"] = 1, ["param1"] = 11, ["z"] = 14, ["name"] = "default:water_source" }, { ["x"] = 1, ["meta"] = { ["fields"] = {  }, ["inventory"] = {  } }, ["param2"] = 240, ["y"] = 1, ["param1"] = 11, ["z"] = 15, ["name"] = "default:water_source" }, { ["x"] = 1, ["meta"] = { ["fields"] = {  }, ["inventory"] = {  } }, ["param2"] = 240, ["y"] = 1, ["param1"] = 11, ["z"] = 16, ["name"] = "default:water_source" }, { ["x"] = 1, ["meta"] = { ["fields"] = {  }, ["inventory"] = {  } }, ["param2"] = 240, ["y"] = 1, ["param1"] = 11, ["z"] = 17, ["name"] = "default:water_source" }, { ["x"] = 1, ["meta"] = { ["fields"] = {  }, ["inventory"] = {  } }, ["param2"] = 240, ["y"] = 1, ["param1"] = 11, ["z"] = 18, ["name"] = "default:water_source" }, { ["x"] = 1, ["meta"] = { ["fields"] = {  }, ["inventory"] = {  } }, ["param2"] = 240, ["y"] = 1, ["param1"] = 11, ["z"] = 19, ["name"] = "default:water_source" }, { ["x"] = 1, ["meta"] = { ["fields"] = {  }, ["inventory"] = {  } }, ["param2"] = 240, ["y"] = 1, ["param1"] = 11, ["z"] = 20, ["name"] = "default:water_source" }, { ["x"] = 1, ["meta"] = { ["fields"] = {  }, ["inventory"] = {  } }, ["param2"] = 240, ["y"] = 1, ["param1"] = 11, ["z"] = 21, ["name"] = "default:water_source" }, { ["x"] = 1, ["meta"] = { ["fields"] = {  }, ["inventory"] = {  } }, ["param2"] = 240, ["y"] = 1, ["param1"] = 11, ["z"] = 22, ["name"] = "default:water_source" }, { ["x"] = 1, ["meta"] = { ["fields"] = {  }, ["inventory"] = {  } }, ["param2"] = 240, ["y"] = 1, ["param1"] = 11, ["z"] = 23, ["name"] = "default:water_source" }, { ["x"] = 1, ["meta"] = { ["fields"] = {  }, ["inventory"] = {  } }, ["param2"] = 240, ["y"] = 1, ["param1"] = 11, ["z"] = 24, ["name"] = "default:water_source" }, { ["x"] = 1, ["meta"] = { ["fields"] = {  }, ["inventory"] = {  } }, ["param2"] = 240, ["y"] = 1, ["param1"] = 11, ["z"] = 25, ["name"] = "default:water_source" }, { ["x"] = 1, ["meta"] = { ["fields"] = {  }, ["inventory"] = {  } }, ["param2"] = 240, ["y"] = 1, ["param1"] = 11, ["z"] = 26, ["name"] = "default:water_source" }, { ["x"] = 1, ["meta"] = { ["fields"] = {  }, ["inventory"] = {  } }, ["param2"] = 240, ["y"] = 1, ["param1"] = 11, ["z"] = 27, ["name"] = "default:water_source" }, { ["x"] = 1, ["meta"] = { ["fields"] = {  }, ["inventory"] = {  } }, ["param2"] = 240, ["y"] = 1, ["param1"] = 11, ["z"] = 28, ["name"] = "default:water_source" }, { ["x"] = 1, ["meta"] = { ["fields"] = {  }, ["inventory"] = {  } }, ["param2"] = 240, ["y"] = 1, ["param1"] = 11, ["z"] = 29, ["name"] = "default:water_source" }, { ["x"] = 1, ["meta"] = { ["fields"] = {  }, ["inventory"] = {  } }, ["param2"] = 240, ["y"] = 1, ["param1"] = 11, ["z"] = 30, ["name"] = "default:water_source" }, { ["x"] = 1, ["meta"] = { ["fields"] = {  }, ["inventory"] = {  } }, ["param2"] = 240, ["y"] = 1, ["param1"] = 11, ["z"] = 31, ["name"] = "default:water_source" }, { ["x"] = 1, ["meta"] = { ["fields"] = {  }, ["inventory"] = {  } }, ["param2"] = 240, ["y"] = 1, ["param1"] = 11, ["z"] = 32, ["name"] = "default:water_source" }, { ["x"] = 1, ["meta"] = { ["fields"] = {  }, ["inventory"] = {  } }, ["param2"] = 240, ["y"] = 1, ["param1"] = 11, ["z"] = 33, ["name"] = "default:water_source" }, { ["x"] = 1, ["meta"] = { ["fields"] = {  }, ["inventory"] = {  } }, ["param2"] = 240, ["y"] = 1, ["param1"] = 11, ["z"] = 34, ["name"] = "default:water_source" }, { ["x"] = 1, ["meta"] = { ["fields"] = {  }, ["inventory"] = {  } }, ["param2"] = 0, ["y"] = 1, ["param1"] = 11, ["z"] = 35, ["name"] = "default:water_source" }, { ["x"] = 1, ["meta"] = { ["fields"] = {  }, ["inventory"] = {  } }, ["param2"] = 0, ["y"] = 1, ["param1"] = 11, ["z"] = 36, ["name"] = "default:water_source" }, { ["x"] = 1, ["meta"] = { ["fields"] = {  }, ["inventory"] = {  } }, ["param2"] = 0, ["y"] = 1, ["param1"] = 11, ["z"] = 37, ["name"] = "default:water_source" }, { ["x"] = 1, ["meta"] = { ["fields"] = {  }, ["inventory"] = {  } }, ["param2"] = 0, ["y"] = 1, ["param1"] = 11, ["z"] = 38, ["name"] = "default:water_source" }, { ["x"] = 1, ["meta"] = { ["fields"] = {  }, ["inventory"] = {  } }, ["param2"] = 0, ["y"] = 1, ["param1"] = 11, ["z"] = 39, ["name"] = "default:water_source" }, { ["x"] = 1, ["meta"] = { ["fields"] = {  }, ["inventory"] = {  } }, ["param2"] = 0, ["y"] = 1, ["param1"] = 11, ["z"] = 40, ["name"] = "default:water_source" }, { ["x"] = 1, ["meta"] = { ["fields"] = {  }, ["inventory"] = {  } }, ["param2"] = 0, ["y"] = 1, ["param1"] = 11, ["z"] = 41, ["name"] = "default:water_source" }, { ["x"] = 1, ["meta"] = { ["fields"] = {  }, ["inventory"] = {  } }, ["param2"] = 0, ["y"] = 2, ["param1"] = 12, ["z"] = 0, ["name"] = "default:water_source" }, { ["x"] = 1, ["meta"] = { ["fields"] = {  }, ["inventory"] = {  } }, ["param2"] = 0, ["y"] = 2, ["param1"] = 12, ["z"] = 1, ["name"] = "default:water_source" }, { ["x"] = 1, ["meta"] = { ["fields"] = {  }, ["inventory"] = {  } }, ["param2"] = 0, ["y"] = 2, ["param1"] = 12, ["z"] = 2, ["name"] = "default:water_source" }, { ["x"] = 1, ["meta"] = { ["fields"] = {  }, ["inventory"] = {  } }, ["param2"] = 0, ["y"] = 2, ["param1"] = 12, ["z"] = 3, ["name"] = "default:water_source" }, { ["x"] = 1, ["meta"] = { ["fields"] = {  }, ["inventory"] = {  } }, ["param2"] = 0, ["y"] = 2, ["param1"] = 12, ["z"] = 4, ["name"] = "default:water_source" }, { ["x"] = 1, ["meta"] = { ["fields"] = {  }, ["inventory"] = {  } }, ["param2"] = 0, ["y"] = 2, ["param1"] = 12, ["z"] = 5, ["name"] = "default:water_source" }, { ["x"] = 1, ["meta"] = { ["fields"] = {  }, ["inventory"] = {  } }, ["param2"] = 0, ["y"] = 2, ["param1"] = 12, ["z"] = 6, ["name"] = "default:water_source" }, { ["x"] = 1, ["meta"] = { ["fields"] = {  }, ["inventory"] = {  } }, ["param2"] = 0, ["y"] = 2, ["param1"] = 12, ["z"] = 7, ["name"] = "default:water_source" }, { ["x"] = 1, ["meta"] = { ["fields"] = {  }, ["inventory"] = {  } }, ["param2"] = 0, ["y"] = 2, ["param1"] = 12, ["z"] = 8, ["name"] = "default:water_source" }, { ["x"] = 1, ["meta"] = { ["fields"] = {  }, ["inventory"] = {  } }, ["param2"] = 0, ["y"] = 2, ["param1"] = 12, ["z"] = 9, ["name"] = "default:water_source" }, { ["x"] = 1, ["meta"] = { ["fields"] = {  }, ["inventory"] = {  } }, ["param2"] = 0, ["y"] = 2, ["param1"] = 12, ["z"] = 10, ["name"] = "default:water_source" }, { ["x"] = 1, ["meta"] = { ["fields"] = {  }, ["inventory"] = {  } }, ["param2"] = 0, ["y"] = 2, ["param1"] = 12, ["z"] = 11, ["name"] = "default:water_source" }, { ["x"] = 1, ["meta"] = { ["fields"] = {  }, ["inventory"] = {  } }, ["param2"] = 0, ["y"] = 2, ["param1"] = 12, ["z"] = 12, ["name"] = "default:water_source" }, { ["x"] = 1, ["meta"] = { ["fields"] = {  }, ["inventory"] = {  } }, ["param2"] = 0, ["y"] = 2, ["param1"] = 12, ["z"] = 13, ["name"] = "default:water_source" }, { ["x"] = 1, ["meta"] = { ["fields"] = {  }, ["inventory"] = {  } }, ["param2"] = 0, ["y"] = 2, ["param1"] = 12, ["z"] = 14, ["name"] = "default:water_source" }, { ["x"] = 1, ["meta"] = { ["fields"] = {  }, ["inventory"] = {  } }, ["param2"] = 0, ["y"] = 2, ["param1"] = 12, ["z"] = 15, ["name"] = "default:water_source" }, { ["x"] = 1, ["meta"] = { ["fields"] = {  }, ["inventory"] = {  } }, ["param2"] = 0, ["y"] = 2, ["param1"] = 12, ["z"] = 16, ["name"] = "default:water_source" }, { ["x"] = 1, ["meta"] = { ["fields"] = {  }, ["inventory"] = {  } }, ["param2"] = 0, ["y"] = 2, ["param1"] = 12, ["z"] = 17, ["name"] = "default:water_source" }, { ["x"] = 1, ["meta"] = { ["fields"] = {  }, ["inventory"] = {  } }, ["param2"] = 0, ["y"] = 2, ["param1"] = 12, ["z"] = 18, ["name"] = "default:water_source" }, { ["x"] = 1, ["meta"] = { ["fields"] = {  }, ["inventory"] = {  } }, ["param2"] = 0, ["y"] = 2, ["param1"] = 12, ["z"] = 19, ["name"] = "default:water_source" }, { ["x"] = 1, ["meta"] = { ["fields"] = {  }, ["inventory"] = {  } }, ["param2"] = 0, ["y"] = 2, ["param1"] = 12, ["z"] = 20, ["name"] = "default:water_source" }, { ["x"] = 1, ["meta"] = { ["fields"] = {  }, ["inventory"] = {  } }, ["param2"] = 0, ["y"] = 2, ["param1"] = 12, ["z"] = 21, ["name"] = "default:water_source" }, { ["x"] = 1, ["meta"] = { ["fields"] = {  }, ["inventory"] = {  } }, ["param2"] = 0, ["y"] = 2, ["param1"] = 12, ["z"] = 22, ["name"] = "default:water_source" }, { ["x"] = 1, ["meta"] = { ["fields"] = {  }, ["inventory"] = {  } }, ["param2"] = 0, ["y"] = 2, ["param1"] = 12, ["z"] = 23, ["name"] = "default:water_source" }, { ["x"] = 1, ["meta"] = { ["fields"] = {  }, ["inventory"] = {  } }, ["param2"] = 0, ["y"] = 2, ["param1"] = 12, ["z"] = 24, ["name"] = "default:water_source" }, { ["x"] = 1, ["meta"] = { ["fields"] = {  }, ["inventory"] = {  } }, ["param2"] = 0, ["y"] = 2, ["param1"] = 12, ["z"] = 25, ["name"] = "default:water_source" }, { ["x"] = 1, ["meta"] = { ["fields"] = {  }, ["inventory"] = {  } }, ["param2"] = 0, ["y"] = 2, ["param1"] = 12, ["z"] = 26, ["name"] = "default:water_source" }, { ["x"] = 1, ["meta"] = { ["fields"] = {  }, ["inventory"] = {  } }, ["param2"] = 0, ["y"] = 2, ["param1"] = 12, ["z"] = 27, ["name"] = "default:water_source" }, { ["x"] = 1, ["meta"] = { ["fields"] = {  }, ["inventory"] = {  } }, ["param2"] = 0, ["y"] = 2, ["param1"] = 12, ["z"] = 28, ["name"] = "default:water_source" }, { ["x"] = 1, ["meta"] = { ["fields"] = {  }, ["inventory"] = {  } }, ["param2"] = 0, ["y"] = 2, ["param1"] = 12, ["z"] = 29, ["name"] = "default:water_source" }, { ["x"] = 1, ["meta"] = { ["fields"] = {  }, ["inventory"] = {  } }, ["param2"] = 0, ["y"] = 2, ["param1"] = 12, ["z"] = 30, ["name"] = "default:water_source" }, { ["x"] = 1, ["meta"] = { ["fields"] = {  }, ["inventory"] = {  } }, ["param2"] = 0, ["y"] = 2, ["param1"] = 12, ["z"] = 31, ["name"] = "default:water_source" }, { ["x"] = 1, ["meta"] = { ["fields"] = {  }, ["inventory"] = {  } }, ["param2"] = 0, ["y"] = 2, ["param1"] = 12, ["z"] = 32, ["name"] = "default:water_source" }, { ["x"] = 1, ["meta"] = { ["fields"] = {  }, ["inventory"] = {  } }, ["param2"] = 0, ["y"] = 2, ["param1"] = 12, ["z"] = 33, ["name"] = "default:water_source" }, { ["x"] = 1, ["meta"] = { ["fields"] = {  }, ["inventory"] = {  } }, ["param2"] = 0, ["y"] = 2, ["param1"] = 12, ["z"] = 34, ["name"] = "default:water_source" }, { ["x"] = 1, ["meta"] = { ["fields"] = {  }, ["inventory"] = {  } }, ["param2"] = 0, ["y"] = 2, ["param1"] = 12, ["z"] = 35, ["name"] = "default:water_source" }, { ["x"] = 1, ["meta"] = { ["fields"] = {  }, ["inventory"] = {  } }, ["param2"] = 0, ["y"] = 2, ["param1"] = 12, ["z"] = 36, ["name"] = "default:water_source" }, { ["x"] = 1, ["meta"] = { ["fields"] = {  }, ["inventory"] = {  } }, ["param2"] = 0, ["y"] = 2, ["param1"] = 12, ["z"] = 37, ["name"] = "default:water_source" }, { ["x"] = 1, ["meta"] = { ["fields"] = {  }, ["inventory"] = {  } }, ["param2"] = 0, ["y"] = 2, ["param1"] = 12, ["z"] = 38, ["name"] = "default:water_source" }, { ["x"] = 1, ["meta"] = { ["fields"] = {  }, ["inventory"] = {  } }, ["param2"] = 0, ["y"] = 2, ["param1"] = 12, ["z"] = 39, ["name"] = "default:water_source" }, { ["x"] = 1, ["meta"] = { ["fields"] = {  }, ["inventory"] = {  } }, ["param2"] = 0, ["y"] = 2, ["param1"] = 12, ["z"] = 40, ["name"] = "default:water_source" }, { ["x"] = 1, ["meta"] = { ["fields"] = {  }, ["inventory"] = {  } }, ["param2"] = 0, ["y"] = 2, ["param1"] = 12, ["z"] = 41, ["name"] = "default:water_source" }, { ["x"] = 1, ["meta"] = { ["fields"] = {  }, ["inventory"] = {  } }, ["param2"] = 0, ["y"] = 3, ["param1"] = 13, ["z"] = 0, ["name"] = "default:water_source" }, { ["x"] = 1, ["meta"] = { ["fields"] = {  }, ["inventory"] = {  } }, ["param2"] = 0, ["y"] = 3, ["param1"] = 13, ["z"] = 1, ["name"] = "default:water_source" }, { ["x"] = 1, ["meta"] = { ["fields"] = {  }, ["inventory"] = {  } }, ["param2"] = 0, ["y"] = 3, ["param1"] = 13, ["z"] = 2, ["name"] = "default:water_source" }, { ["x"] = 1, ["meta"] = { ["fields"] = {  }, ["inventory"] = {  } }, ["param2"] = 0, ["y"] = 3, ["param1"] = 13, ["z"] = 3, ["name"] = "default:water_source" }, { ["x"] = 1, ["meta"] = { ["fields"] = {  }, ["inventory"] = {  } }, ["param2"] = 0, ["y"] = 3, ["param1"] = 13, ["z"] = 4, ["name"] = "default:water_source" }, { ["x"] = 1, ["meta"] = { ["fields"] = {  }, ["inventory"] = {  } }, ["param2"] = 0, ["y"] = 3, ["param1"] = 13, ["z"] = 5, ["name"] = "default:water_source" }, { ["x"] = 1, ["meta"] = { ["fields"] = {  }, ["inventory"] = {  } }, ["param2"] = 0, ["y"] = 3, ["param1"] = 13, ["z"] = 6, ["name"] = "default:water_source" }, { ["x"] = 1, ["meta"] = { ["fields"] = {  }, ["inventory"] = {  } }, ["param2"] = 0, ["y"] = 3, ["param1"] = 13, ["z"] = 7, ["name"] = "default:water_source" }, { ["x"] = 1, ["meta"] = { ["fields"] = {  }, ["inventory"] = {  } }, ["param2"] = 0, ["y"] = 3, ["param1"] = 13, ["z"] = 8, ["name"] = "default:water_source" }, { ["x"] = 1, ["meta"] = { ["fields"] = {  }, ["inventory"] = {  } }, ["param2"] = 0, ["y"] = 3, ["param1"] = 13, ["z"] = 9, ["name"] = "default:water_source" }, { ["x"] = 1, ["meta"] = { ["fields"] = {  }, ["inventory"] = {  } }, ["param2"] = 0, ["y"] = 3, ["param1"] = 13, ["z"] = 10, ["name"] = "default:water_source" }, { ["x"] = 1, ["meta"] = { ["fields"] = {  }, ["inventory"] = {  } }, ["param2"] = 0, ["y"] = 3, ["param1"] = 13, ["z"] = 11, ["name"] = "default:water_source" }, { ["x"] = 1, ["meta"] = { ["fields"] = {  }, ["inventory"] = {  } }, ["param2"] = 0, ["y"] = 3, ["param1"] = 13, ["z"] = 12, ["name"] = "default:water_source" }, { ["x"] = 1, ["meta"] = { ["fields"] = {  }, ["inventory"] = {  } }, ["param2"] = 0, ["y"] = 3, ["param1"] = 13, ["z"] = 13, ["name"] = "default:water_source" }, { ["x"] = 1, ["meta"] = { ["fields"] = {  }, ["inventory"] = {  } }, ["param2"] = 0, ["y"] = 3, ["param1"] = 13, ["z"] = 14, ["name"] = "default:water_source" }, { ["x"] = 1, ["meta"] = { ["fields"] = {  }, ["inventory"] = {  } }, ["param2"] = 0, ["y"] = 3, ["param1"] = 13, ["z"] = 15, ["name"] = "default:water_source" }, { ["x"] = 1, ["meta"] = { ["fields"] = {  }, ["inventory"] = {  } }, ["param2"] = 0, ["y"] = 3, ["param1"] = 13, ["z"] = 16, ["name"] = "default:water_source" }, { ["x"] = 1, ["meta"] = { ["fields"] = {  }, ["inventory"] = {  } }, ["param2"] = 0, ["y"] = 3, ["param1"] = 13, ["z"] = 17, ["name"] = "default:water_source" }, { ["x"] = 1, ["meta"] = { ["fields"] = {  }, ["inventory"] = {  } }, ["param2"] = 0, ["y"] = 3, ["param1"] = 13, ["z"] = 18, ["name"] = "default:water_source" }, { ["x"] = 1, ["meta"] = { ["fields"] = {  }, ["inventory"] = {  } }, ["param2"] = 0, ["y"] = 3, ["param1"] = 13, ["z"] = 19, ["name"] = "default:water_source" }, { ["x"] = 1, ["meta"] = { ["fields"] = {  }, ["inventory"] = {  } }, ["param2"] = 0, ["y"] = 3, ["param1"] = 13, ["z"] = 20, ["name"] = "default:water_source" }, { ["x"] = 1, ["meta"] = { ["fields"] = {  }, ["inventory"] = {  } }, ["param2"] = 0, ["y"] = 3, ["param1"] = 13, ["z"] = 21, ["name"] = "default:water_source" }, { ["x"] = 1, ["meta"] = { ["fields"] = {  }, ["inventory"] = {  } }, ["param2"] = 0, ["y"] = 3, ["param1"] = 13, ["z"] = 22, ["name"] = "default:water_source" }, { ["x"] = 1, ["meta"] = { ["fields"] = {  }, ["inventory"] = {  } }, ["param2"] = 0, ["y"] = 3, ["param1"] = 13, ["z"] = 23, ["name"] = "default:water_source" }, { ["x"] = 1, ["meta"] = { ["fields"] = {  }, ["inventory"] = {  } }, ["param2"] = 0, ["y"] = 3, ["param1"] = 13, ["z"] = 24, ["name"] = "default:water_source" }, { ["x"] = 1, ["meta"] = { ["fields"] = {  }, ["inventory"] = {  } }, ["param2"] = 0, ["y"] = 3, ["param1"] = 13, ["z"] = 25, ["name"] = "default:water_source" }, { ["x"] = 1, ["meta"] = { ["fields"] = {  }, ["inventory"] = {  } }, ["param2"] = 0, ["y"] = 3, ["param1"] = 13, ["z"] = 26, ["name"] = "default:water_source" }, { ["x"] = 1, ["meta"] = { ["fields"] = {  }, ["inventory"] = {  } }, ["param2"] = 0, ["y"] = 3, ["param1"] = 13, ["z"] = 27, ["name"] = "default:water_source" }, { ["x"] = 1, ["meta"] = { ["fields"] = {  }, ["inventory"] = {  } }, ["param2"] = 0, ["y"] = 3, ["param1"] = 13, ["z"] = 28, ["name"] = "default:water_source" }, { ["x"] = 1, ["meta"] = { ["fields"] = {  }, ["inventory"] = {  } }, ["param2"] = 0, ["y"] = 3, ["param1"] = 13, ["z"] = 29, ["name"] = "default:water_source" }, { ["x"] = 1, ["meta"] = { ["fields"] = {  }, ["inventory"] = {  } }, ["param2"] = 0, ["y"] = 3, ["param1"] = 13, ["z"] = 30, ["name"] = "default:water_source" }, { ["x"] = 1, ["meta"] = { ["fields"] = {  }, ["inventory"] = {  } }, ["param2"] = 0, ["y"] = 3, ["param1"] = 13, ["z"] = 31, ["name"] = "default:water_source" }, { ["x"] = 1, ["meta"] = { ["fields"] = {  }, ["inventory"] = {  } }, ["param2"] = 0, ["y"] = 3, ["param1"] = 13, ["z"] = 32, ["name"] = "default:water_source" }, { ["x"] = 1, ["meta"] = { ["fields"] = {  }, ["inventory"] = {  } }, ["param2"] = 0, ["y"] = 3, ["param1"] = 13, ["z"] = 33, ["name"] = "default:water_source" }, { ["x"] = 1, ["meta"] = { ["fields"] = {  }, ["inventory"] = {  } }, ["param2"] = 0, ["y"] = 3, ["param1"] = 13, ["z"] = 34, ["name"] = "default:water_source" }, { ["x"] = 1, ["meta"] = { ["fields"] = {  }, ["inventory"] = {  } }, ["param2"] = 0, ["y"] = 3, ["param1"] = 13, ["z"] = 35, ["name"] = "default:water_source" }, { ["x"] = 1, ["meta"] = { ["fields"] = {  }, ["inventory"] = {  } }, ["param2"] = 0, ["y"] = 3, ["param1"] = 13, ["z"] = 36, ["name"] = "default:water_source" }, { ["x"] = 1, ["meta"] = { ["fields"] = {  }, ["inventory"] = {  } }, ["param2"] = 0, ["y"] = 3, ["param1"] = 13, ["z"] = 37, ["name"] = "default:water_source" }, { ["x"] = 1, ["meta"] = { ["fields"] = {  }, ["inventory"] = {  } }, ["param2"] = 0, ["y"] = 3, ["param1"] = 13, ["z"] = 38, ["name"] = "default:water_source" }, { ["x"] = 1, ["meta"] = { ["fields"] = {  }, ["inventory"] = {  } }, ["param2"] = 0, ["y"] = 3, ["param1"] = 13, ["z"] = 39, ["name"] = "default:water_source" }, { ["x"] = 1, ["meta"] = { ["fields"] = {  }, ["inventory"] = {  } }, ["param2"] = 0, ["y"] = 3, ["param1"] = 13, ["z"] = 40, ["name"] = "default:water_source" }, { ["x"] = 1, ["meta"] = { ["fields"] = {  }, ["inventory"] = {  } }, ["param2"] = 0, ["y"] = 3, ["param1"] = 13, ["z"] = 41, ["name"] = "default:water_source" }, { ["x"] = 2, ["meta"] = { ["fields"] = {  }, ["inventory"] = {  } }, ["param2"] = 0, ["y"] = 0, ["param1"] = 10, ["z"] = 0, ["name"] = "default:water_source" }, { ["x"] = 2, ["meta"] = { ["fields"] = {  }, ["inventory"] = {  } }, ["param2"] = 0, ["y"] = 0, ["param1"] = 10, ["z"] = 1, ["name"] = "default:water_source" }, { ["x"] = 2, ["meta"] = { ["fields"] = {  }, ["inventory"] = {  } }, ["param2"] = 0, ["y"] = 0, ["param1"] = 10, ["z"] = 2, ["name"] = "default:water_source" }, { ["x"] = 2, ["meta"] = { ["fields"] = {  }, ["inventory"] = {  } }, ["param2"] = 0, ["y"] = 0, ["param1"] = 10, ["z"] = 3, ["name"] = "default:water_source" }, { ["x"] = 2, ["meta"] = { ["fields"] = {  }, ["inventory"] = {  } }, ["param2"] = 0, ["y"] = 0, ["param1"] = 10, ["z"] = 4, ["name"] = "default:water_source" }, { ["x"] = 2, ["meta"] = { ["fields"] = {  }, ["inventory"] = {  } }, ["param2"] = 0, ["y"] = 0, ["param1"] = 10, ["z"] = 5, ["name"] = "default:water_source" }, { ["x"] = 2, ["meta"] = { ["fields"] = {  }, ["inventory"] = {  } }, ["param2"] = 0, ["y"] = 0, ["param1"] = 10, ["z"] = 6, ["name"] = "default:water_source" }, { ["x"] = 2, ["meta"] = { ["fields"] = {  }, ["inventory"] = {  } }, ["param2"] = 240, ["y"] = 0, ["param1"] = 10, ["z"] = 7, ["name"] = "default:water_source" }, { ["x"] = 2, ["meta"] = { ["fields"] = {  }, ["inventory"] = {  } }, ["param2"] = 240, ["y"] = 0, ["param1"] = 10, ["z"] = 8, ["name"] = "default:water_source" }, { ["x"] = 2, ["meta"] = { ["fields"] = {  }, ["inventory"] = {  } }, ["param2"] = 240, ["y"] = 0, ["param1"] = 10, ["z"] = 9, ["name"] = "default:water_source" }, { ["x"] = 2, ["meta"] = { ["fields"] = {  }, ["inventory"] = {  } }, ["param2"] = 240, ["y"] = 0, ["param1"] = 10, ["z"] = 10, ["name"] = "default:water_source" }, { ["x"] = 2, ["meta"] = { ["fields"] = {  }, ["inventory"] = {  } }, ["param2"] = 240, ["y"] = 0, ["param1"] = 10, ["z"] = 11, ["name"] = "default:water_source" }, { ["x"] = 2, ["meta"] = { ["fields"] = {  }, ["inventory"] = {  } }, ["param2"] = 240, ["y"] = 0, ["param1"] = 10, ["z"] = 12, ["name"] = "default:water_source" }, { ["x"] = 2, ["meta"] = { ["fields"] = {  }, ["inventory"] = {  } }, ["param2"] = 240, ["y"] = 0, ["param1"] = 10, ["z"] = 13, ["name"] = "default:water_source" }, { ["x"] = 2, ["meta"] = { ["fields"] = {  }, ["inventory"] = {  } }, ["param2"] = 240, ["y"] = 0, ["param1"] = 10, ["z"] = 14, ["name"] = "default:water_source" }, { ["x"] = 2, ["meta"] = { ["fields"] = {  }, ["inventory"] = {  } }, ["param2"] = 240, ["y"] = 0, ["param1"] = 10, ["z"] = 15, ["name"] = "default:water_source" }, { ["x"] = 2, ["meta"] = { ["fields"] = {  }, ["inventory"] = {  } }, ["param2"] = 240, ["y"] = 0, ["param1"] = 10, ["z"] = 16, ["name"] = "default:water_source" }, { ["x"] = 2, ["meta"] = { ["fields"] = {  }, ["inventory"] = {  } }, ["param2"] = 240, ["y"] = 0, ["param1"] = 10, ["z"] = 17, ["name"] = "default:water_source" }, { ["x"] = 2, ["meta"] = { ["fields"] = {  }, ["inventory"] = {  } }, ["param2"] = 240, ["y"] = 0, ["param1"] = 10, ["z"] = 18, ["name"] = "default:water_source" }, { ["x"] = 2, ["meta"] = { ["fields"] = {  }, ["inventory"] = {  } }, ["param2"] = 240, ["y"] = 0, ["param1"] = 10, ["z"] = 19, ["name"] = "default:water_source" }, { ["x"] = 2, ["meta"] = { ["fields"] = {  }, ["inventory"] = {  } }, ["param2"] = 240, ["y"] = 0, ["param1"] = 10, ["z"] = 20, ["name"] = "default:water_source" }, { ["x"] = 2, ["meta"] = { ["fields"] = {  }, ["inventory"] = {  } }, ["param2"] = 240, ["y"] = 0, ["param1"] = 10, ["z"] = 21, ["name"] = "default:water_source" }, { ["x"] = 2, ["meta"] = { ["fields"] = {  }, ["inventory"] = {  } }, ["param2"] = 240, ["y"] = 0, ["param1"] = 10, ["z"] = 22, ["name"] = "default:water_source" }, { ["x"] = 2, ["meta"] = { ["fields"] = {  }, ["inventory"] = {  } }, ["param2"] = 240, ["y"] = 0, ["param1"] = 10, ["z"] = 23, ["name"] = "default:water_source" }, { ["x"] = 2, ["meta"] = { ["fields"] = {  }, ["inventory"] = {  } }, ["param2"] = 240, ["y"] = 0, ["param1"] = 10, ["z"] = 24, ["name"] = "default:water_source" }, { ["x"] = 2, ["meta"] = { ["fields"] = {  }, ["inventory"] = {  } }, ["param2"] = 240, ["y"] = 0, ["param1"] = 10, ["z"] = 25, ["name"] = "default:water_source" }, { ["x"] = 2, ["meta"] = { ["fields"] = {  }, ["inventory"] = {  } }, ["param2"] = 240, ["y"] = 0, ["param1"] = 10, ["z"] = 26, ["name"] = "default:water_source" }, { ["x"] = 2, ["meta"] = { ["fields"] = {  }, ["inventory"] = {  } }, ["param2"] = 240, ["y"] = 0, ["param1"] = 10, ["z"] = 27, ["name"] = "default:water_source" }, { ["x"] = 2, ["meta"] = { ["fields"] = {  }, ["inventory"] = {  } }, ["param2"] = 240, ["y"] = 0, ["param1"] = 10, ["z"] = 28, ["name"] = "default:water_source" }, { ["x"] = 2, ["meta"] = { ["fields"] = {  }, ["inventory"] = {  } }, ["param2"] = 240, ["y"] = 0, ["param1"] = 10, ["z"] = 29, ["name"] = "default:water_source" }, { ["x"] = 2, ["meta"] = { ["fields"] = {  }, ["inventory"] = {  } }, ["param2"] = 240, ["y"] = 0, ["param1"] = 10, ["z"] = 30, ["name"] = "default:water_source" }, { ["x"] = 2, ["meta"] = { ["fields"] = {  }, ["inventory"] = {  } }, ["param2"] = 240, ["y"] = 0, ["param1"] = 10, ["z"] = 31, ["name"] = "default:water_source" }, { ["x"] = 2, ["meta"] = { ["fields"] = {  }, ["inventory"] = {  } }, ["param2"] = 240, ["y"] = 0, ["param1"] = 10, ["z"] = 32, ["name"] = "default:water_source" }, { ["x"] = 2, ["meta"] = { ["fields"] = {  }, ["inventory"] = {  } }, ["param2"] = 240, ["y"] = 0, ["param1"] = 10, ["z"] = 33, ["name"] = "default:water_source" }, { ["x"] = 2, ["meta"] = { ["fields"] = {  }, ["inventory"] = {  } }, ["param2"] = 240, ["y"] = 0, ["param1"] = 10, ["z"] = 34, ["name"] = "default:water_source" }, { ["x"] = 2, ["meta"] = { ["fields"] = {  }, ["inventory"] = {  } }, ["param2"] = 0, ["y"] = 0, ["param1"] = 10, ["z"] = 35, ["name"] = "default:water_source" }, { ["x"] = 2, ["meta"] = { ["fields"] = {  }, ["inventory"] = {  } }, ["param2"] = 0, ["y"] = 0, ["param1"] = 10, ["z"] = 36, ["name"] = "default:water_source" }, { ["x"] = 2, ["meta"] = { ["fields"] = {  }, ["inventory"] = {  } }, ["param2"] = 0, ["y"] = 0, ["param1"] = 10, ["z"] = 37, ["name"] = "default:water_source" }, { ["x"] = 2, ["meta"] = { ["fields"] = {  }, ["inventory"] = {  } }, ["param2"] = 0, ["y"] = 0, ["param1"] = 10, ["z"] = 38, ["name"] = "default:water_source" }, { ["x"] = 2, ["meta"] = { ["fields"] = {  }, ["inventory"] = {  } }, ["param2"] = 0, ["y"] = 0, ["param1"] = 10, ["z"] = 39, ["name"] = "default:water_source" }, { ["x"] = 2, ["meta"] = { ["fields"] = {  }, ["inventory"] = {  } }, ["param2"] = 0, ["y"] = 0, ["param1"] = 10, ["z"] = 40, ["name"] = "default:water_source" }, { ["x"] = 2, ["meta"] = { ["fields"] = {  }, ["inventory"] = {  } }, ["param2"] = 0, ["y"] = 0, ["param1"] = 10, ["z"] = 41, ["name"] = "default:water_source" }, { ["x"] = 2, ["meta"] = { ["fields"] = {  }, ["inventory"] = {  } }, ["param2"] = 0, ["y"] = 1, ["param1"] = 11, ["z"] = 0, ["name"] = "default:water_source" }, { ["x"] = 2, ["meta"] = { ["fields"] = {  }, ["inventory"] = {  } }, ["param2"] = 0, ["y"] = 1, ["param1"] = 11, ["z"] = 1, ["name"] = "default:water_source" }, { ["x"] = 2, ["meta"] = { ["fields"] = {  }, ["inventory"] = {  } }, ["param2"] = 0, ["y"] = 1, ["param1"] = 11, ["z"] = 2, ["name"] = "default:water_source" }, { ["x"] = 2, ["meta"] = { ["fields"] = {  }, ["inventory"] = {  } }, ["param2"] = 0, ["y"] = 1, ["param1"] = 11, ["z"] = 3, ["name"] = "default:water_source" }, { ["x"] = 2, ["meta"] = { ["fields"] = {  }, ["inventory"] = {  } }, ["param2"] = 0, ["y"] = 1, ["param1"] = 11, ["z"] = 4, ["name"] = "default:water_source" }, { ["x"] = 2, ["meta"] = { ["fields"] = {  }, ["inventory"] = {  } }, ["param2"] = 0, ["y"] = 1, ["param1"] = 11, ["z"] = 5, ["name"] = "default:water_source" }, { ["x"] = 2, ["meta"] = { ["fields"] = {  }, ["inventory"] = {  } }, ["param2"] = 0, ["y"] = 1, ["param1"] = 11, ["z"] = 6, ["name"] = "default:water_source" }, { ["x"] = 2, ["meta"] = { ["fields"] = {  }, ["inventory"] = {  } }, ["param2"] = 240, ["y"] = 1, ["param1"] = 11, ["z"] = 7, ["name"] = "default:water_source" }, { ["x"] = 2, ["meta"] = { ["fields"] = {  }, ["inventory"] = {  } }, ["param2"] = 240, ["y"] = 1, ["param1"] = 11, ["z"] = 8, ["name"] = "default:water_source" }, { ["x"] = 2, ["meta"] = { ["fields"] = {  }, ["inventory"] = {  } }, ["param2"] = 240, ["y"] = 1, ["param1"] = 11, ["z"] = 9, ["name"] = "default:water_source" }, { ["x"] = 2, ["meta"] = { ["fields"] = {  }, ["inventory"] = {  } }, ["param2"] = 240, ["y"] = 1, ["param1"] = 11, ["z"] = 10, ["name"] = "default:water_source" }, { ["x"] = 2, ["meta"] = { ["fields"] = {  }, ["inventory"] = {  } }, ["param2"] = 240, ["y"] = 1, ["param1"] = 11, ["z"] = 11, ["name"] = "default:water_source" }, { ["x"] = 2, ["meta"] = { ["fields"] = {  }, ["inventory"] = {  } }, ["param2"] = 240, ["y"] = 1, ["param1"] = 11, ["z"] = 12, ["name"] = "default:water_source" }, { ["x"] = 2, ["meta"] = { ["fields"] = {  }, ["inventory"] = {  } }, ["param2"] = 240, ["y"] = 1, ["param1"] = 11, ["z"] = 13, ["name"] = "default:water_source" }, { ["x"] = 2, ["meta"] = { ["fields"] = {  }, ["inventory"] = {  } }, ["param2"] = 240, ["y"] = 1, ["param1"] = 11, ["z"] = 14, ["name"] = "default:water_source" }, { ["x"] = 2, ["meta"] = { ["fields"] = {  }, ["inventory"] = {  } }, ["param2"] = 240, ["y"] = 1, ["param1"] = 11, ["z"] = 15, ["name"] = "default:water_source" }, { ["x"] = 2, ["meta"] = { ["fields"] = {  }, ["inventory"] = {  } }, ["param2"] = 240, ["y"] = 1, ["param1"] = 11, ["z"] = 16, ["name"] = "default:water_source" }, { ["x"] = 2, ["meta"] = { ["fields"] = {  }, ["inventory"] = {  } }, ["param2"] = 240, ["y"] = 1, ["param1"] = 11, ["z"] = 17, ["name"] = "default:water_source" }, { ["x"] = 2, ["meta"] = { ["fields"] = {  }, ["inventory"] = {  } }, ["param2"] = 240, ["y"] = 1, ["param1"] = 11, ["z"] = 18, ["name"] = "default:water_source" }, { ["x"] = 2, ["meta"] = { ["fields"] = {  }, ["inventory"] = {  } }, ["param2"] = 240, ["y"] = 1, ["param1"] = 11, ["z"] = 19, ["name"] = "default:water_source" }, { ["x"] = 2, ["meta"] = { ["fields"] = {  }, ["inventory"] = {  } }, ["param2"] = 240, ["y"] = 1, ["param1"] = 11, ["z"] = 20, ["name"] = "default:water_source" }, { ["x"] = 2, ["meta"] = { ["fields"] = {  }, ["inventory"] = {  } }, ["param2"] = 240, ["y"] = 1, ["param1"] = 11, ["z"] = 21, ["name"] = "default:water_source" }, { ["x"] = 2, ["meta"] = { ["fields"] = {  }, ["inventory"] = {  } }, ["param2"] = 240, ["y"] = 1, ["param1"] = 11, ["z"] = 22, ["name"] = "default:water_source" }, { ["x"] = 2, ["meta"] = { ["fields"] = {  }, ["inventory"] = {  } }, ["param2"] = 240, ["y"] = 1, ["param1"] = 11, ["z"] = 23, ["name"] = "default:water_source" }, { ["x"] = 2, ["meta"] = { ["fields"] = {  }, ["inventory"] = {  } }, ["param2"] = 240, ["y"] = 1, ["param1"] = 11, ["z"] = 24, ["name"] = "default:water_source" }, { ["x"] = 2, ["meta"] = { ["fields"] = {  }, ["inventory"] = {  } }, ["param2"] = 240, ["y"] = 1, ["param1"] = 11, ["z"] = 25, ["name"] = "default:water_source" }, { ["x"] = 2, ["meta"] = { ["fields"] = {  }, ["inventory"] = {  } }, ["param2"] = 240, ["y"] = 1, ["param1"] = 11, ["z"] = 26, ["name"] = "default:water_source" }, { ["x"] = 2, ["meta"] = { ["fields"] = {  }, ["inventory"] = {  } }, ["param2"] = 240, ["y"] = 1, ["param1"] = 11, ["z"] = 27, ["name"] = "default:water_source" }, { ["x"] = 2, ["meta"] = { ["fields"] = {  }, ["inventory"] = {  } }, ["param2"] = 240, ["y"] = 1, ["param1"] = 11, ["z"] = 28, ["name"] = "default:water_source" }, { ["x"] = 2, ["meta"] = { ["fields"] = {  }, ["inventory"] = {  } }, ["param2"] = 240, ["y"] = 1, ["param1"] = 11, ["z"] = 29, ["name"] = "default:water_source" }, { ["x"] = 2, ["meta"] = { ["fields"] = {  }, ["inventory"] = {  } }, ["param2"] = 240, ["y"] = 1, ["param1"] = 11, ["z"] = 30, ["name"] = "default:water_source" }, { ["x"] = 2, ["meta"] = { ["fields"] = {  }, ["inventory"] = {  } }, ["param2"] = 240, ["y"] = 1, ["param1"] = 11, ["z"] = 31, ["name"] = "default:water_source" }, { ["x"] = 2, ["meta"] = { ["fields"] = {  }, ["inventory"] = {  } }, ["param2"] = 240, ["y"] = 1, ["param1"] = 11, ["z"] = 32, ["name"] = "default:water_source" }, { ["x"] = 2, ["meta"] = { ["fields"] = {  }, ["inventory"] = {  } }, ["param2"] = 240, ["y"] = 1, ["param1"] = 11, ["z"] = 33, ["name"] = "default:water_source" }, { ["x"] = 2, ["meta"] = { ["fields"] = {  }, ["inventory"] = {  } }, ["param2"] = 240, ["y"] = 1, ["param1"] = 11, ["z"] = 34, ["name"] = "default:water_source" }, { ["x"] = 2, ["meta"] = { ["fields"] = {  }, ["inventory"] = {  } }, ["param2"] = 0, ["y"] = 1, ["param1"] = 11, ["z"] = 35, ["name"] = "default:water_source" }, { ["x"] = 2, ["meta"] = { ["fields"] = {  }, ["inventory"] = {  } }, ["param2"] = 0, ["y"] = 1, ["param1"] = 11, ["z"] = 36, ["name"] = "default:water_source" }, { ["x"] = 2, ["meta"] = { ["fields"] = {  }, ["inventory"] = {  } }, ["param2"] = 0, ["y"] = 1, ["param1"] = 11, ["z"] = 37, ["name"] = "default:water_source" }, { ["x"] = 2, ["meta"] = { ["fields"] = {  }, ["inventory"] = {  } }, ["param2"] = 0, ["y"] = 1, ["param1"] = 11, ["z"] = 38, ["name"] = "default:water_source" }, { ["x"] = 2, ["meta"] = { ["fields"] = {  }, ["inventory"] = {  } }, ["param2"] = 0, ["y"] = 1, ["param1"] = 11, ["z"] = 39, ["name"] = "default:water_source" }, { ["x"] = 2, ["meta"] = { ["fields"] = {  }, ["inventory"] = {  } }, ["param2"] = 0, ["y"] = 1, ["param1"] = 11, ["z"] = 40, ["name"] = "default:water_source" }, { ["x"] = 2, ["meta"] = { ["fields"] = {  }, ["inventory"] = {  } }, ["param2"] = 0, ["y"] = 1, ["param1"] = 11, ["z"] = 41, ["name"] = "default:water_source" }, { ["x"] = 2, ["meta"] = { ["fields"] = {  }, ["inventory"] = {  } }, ["param2"] = 0, ["y"] = 2, ["param1"] = 12, ["z"] = 0, ["name"] = "default:water_source" }, { ["x"] = 2, ["meta"] = { ["fields"] = {  }, ["inventory"] = {  } }, ["param2"] = 0, ["y"] = 2, ["param1"] = 12, ["z"] = 1, ["name"] = "default:water_source" }, { ["x"] = 2, ["meta"] = { ["fields"] = {  }, ["inventory"] = {  } }, ["param2"] = 0, ["y"] = 2, ["param1"] = 12, ["z"] = 2, ["name"] = "default:water_source" }, { ["x"] = 2, ["meta"] = { ["fields"] = {  }, ["inventory"] = {  } }, ["param2"] = 0, ["y"] = 2, ["param1"] = 12, ["z"] = 3, ["name"] = "default:water_source" }, { ["x"] = 2, ["meta"] = { ["fields"] = {  }, ["inventory"] = {  } }, ["param2"] = 0, ["y"] = 2, ["param1"] = 12, ["z"] = 4, ["name"] = "default:water_source" }, { ["x"] = 2, ["meta"] = { ["fields"] = {  }, ["inventory"] = {  } }, ["param2"] = 0, ["y"] = 2, ["param1"] = 12, ["z"] = 5, ["name"] = "default:water_source" }, { ["x"] = 2, ["meta"] = { ["fields"] = {  }, ["inventory"] = {  } }, ["param2"] = 0, ["y"] = 2, ["param1"] = 12, ["z"] = 6, ["name"] = "default:water_source" }, { ["x"] = 2, ["meta"] = { ["fields"] = {  }, ["inventory"] = {  } }, ["param2"] = 0, ["y"] = 2, ["param1"] = 12, ["z"] = 7, ["name"] = "default:water_source" }, { ["x"] = 2, ["meta"] = { ["fields"] = {  }, ["inventory"] = {  } }, ["param2"] = 0, ["y"] = 2, ["param1"] = 12, ["z"] = 8, ["name"] = "default:water_source" }, { ["x"] = 2, ["meta"] = { ["fields"] = {  }, ["inventory"] = {  } }, ["param2"] = 0, ["y"] = 2, ["param1"] = 12, ["z"] = 9, ["name"] = "default:water_source" }, { ["x"] = 2, ["meta"] = { ["fields"] = {  }, ["inventory"] = {  } }, ["param2"] = 0, ["y"] = 2, ["param1"] = 12, ["z"] = 10, ["name"] = "default:water_source" }, { ["x"] = 2, ["meta"] = { ["fields"] = {  }, ["inventory"] = {  } }, ["param2"] = 0, ["y"] = 2, ["param1"] = 12, ["z"] = 11, ["name"] = "default:water_source" }, { ["x"] = 2, ["meta"] = { ["fields"] = {  }, ["inventory"] = {  } }, ["param2"] = 0, ["y"] = 2, ["param1"] = 12, ["z"] = 12, ["name"] = "default:water_source" }, { ["x"] = 2, ["meta"] = { ["fields"] = {  }, ["inventory"] = {  } }, ["param2"] = 0, ["y"] = 2, ["param1"] = 12, ["z"] = 13, ["name"] = "default:water_source" }, { ["x"] = 2, ["meta"] = { ["fields"] = {  }, ["inventory"] = {  } }, ["param2"] = 0, ["y"] = 2, ["param1"] = 12, ["z"] = 14, ["name"] = "default:water_source" }, { ["x"] = 2, ["meta"] = { ["fields"] = {  }, ["inventory"] = {  } }, ["param2"] = 0, ["y"] = 2, ["param1"] = 12, ["z"] = 15, ["name"] = "default:water_source" }, { ["x"] = 2, ["meta"] = { ["fields"] = {  }, ["inventory"] = {  } }, ["param2"] = 0, ["y"] = 2, ["param1"] = 12, ["z"] = 16, ["name"] = "default:water_source" }, { ["x"] = 2, ["meta"] = { ["fields"] = {  }, ["inventory"] = {  } }, ["param2"] = 0, ["y"] = 2, ["param1"] = 12, ["z"] = 17, ["name"] = "default:water_source" }, { ["x"] = 2, ["meta"] = { ["fields"] = {  }, ["inventory"] = {  } }, ["param2"] = 0, ["y"] = 2, ["param1"] = 12, ["z"] = 18, ["name"] = "default:water_source" }, { ["x"] = 2, ["meta"] = { ["fields"] = {  }, ["inventory"] = {  } }, ["param2"] = 0, ["y"] = 2, ["param1"] = 12, ["z"] = 19, ["name"] = "default:water_source" }, { ["x"] = 2, ["meta"] = { ["fields"] = {  }, ["inventory"] = {  } }, ["param2"] = 0, ["y"] = 2, ["param1"] = 12, ["z"] = 20, ["name"] = "default:water_source" }, { ["x"] = 2, ["meta"] = { ["fields"] = {  }, ["inventory"] = {  } }, ["param2"] = 0, ["y"] = 2, ["param1"] = 12, ["z"] = 21, ["name"] = "default:water_source" }, { ["x"] = 2, ["meta"] = { ["fields"] = {  }, ["inventory"] = {  } }, ["param2"] = 0, ["y"] = 2, ["param1"] = 12, ["z"] = 22, ["name"] = "default:water_source" }, { ["x"] = 2, ["meta"] = { ["fields"] = {  }, ["inventory"] = {  } }, ["param2"] = 0, ["y"] = 2, ["param1"] = 12, ["z"] = 23, ["name"] = "default:water_source" }, { ["x"] = 2, ["meta"] = { ["fields"] = {  }, ["inventory"] = {  } }, ["param2"] = 0, ["y"] = 2, ["param1"] = 12, ["z"] = 24, ["name"] = "default:water_source" }, { ["x"] = 2, ["meta"] = { ["fields"] = {  }, ["inventory"] = {  } }, ["param2"] = 0, ["y"] = 2, ["param1"] = 12, ["z"] = 25, ["name"] = "default:water_source" }, { ["x"] = 2, ["meta"] = { ["fields"] = {  }, ["inventory"] = {  } }, ["param2"] = 0, ["y"] = 2, ["param1"] = 12, ["z"] = 26, ["name"] = "default:water_source" }, { ["x"] = 2, ["meta"] = { ["fields"] = {  }, ["inventory"] = {  } }, ["param2"] = 0, ["y"] = 2, ["param1"] = 12, ["z"] = 27, ["name"] = "default:water_source" }, { ["x"] = 2, ["meta"] = { ["fields"] = {  }, ["inventory"] = {  } }, ["param2"] = 0, ["y"] = 2, ["param1"] = 12, ["z"] = 28, ["name"] = "default:water_source" }, { ["x"] = 2, ["meta"] = { ["fields"] = {  }, ["inventory"] = {  } }, ["param2"] = 0, ["y"] = 2, ["param1"] = 12, ["z"] = 29, ["name"] = "default:water_source" }, { ["x"] = 2, ["meta"] = { ["fields"] = {  }, ["inventory"] = {  } }, ["param2"] = 0, ["y"] = 2, ["param1"] = 12, ["z"] = 30, ["name"] = "default:water_source" }, { ["x"] = 2, ["meta"] = { ["fields"] = {  }, ["inventory"] = {  } }, ["param2"] = 0, ["y"] = 2, ["param1"] = 12, ["z"] = 31, ["name"] = "default:water_source" }, { ["x"] = 2, ["meta"] = { ["fields"] = {  }, ["inventory"] = {  } }, ["param2"] = 0, ["y"] = 2, ["param1"] = 12, ["z"] = 32, ["name"] = "default:water_source" }, { ["x"] = 2, ["meta"] = { ["fields"] = {  }, ["inventory"] = {  } }, ["param2"] = 0, ["y"] = 2, ["param1"] = 12, ["z"] = 33, ["name"] = "default:water_source" }, { ["x"] = 2, ["meta"] = { ["fields"] = {  }, ["inventory"] = {  } }, ["param2"] = 0, ["y"] = 2, ["param1"] = 12, ["z"] = 34, ["name"] = "default:water_source" }, { ["x"] = 2, ["meta"] = { ["fields"] = {  }, ["inventory"] = {  } }, ["param2"] = 0, ["y"] = 2, ["param1"] = 12, ["z"] = 35, ["name"] = "default:water_source" }, { ["x"] = 2, ["meta"] = { ["fields"] = {  }, ["inventory"] = {  } }, ["param2"] = 0, ["y"] = 2, ["param1"] = 12, ["z"] = 36, ["name"] = "default:water_source" }, { ["x"] = 2, ["meta"] = { ["fields"] = {  }, ["inventory"] = {  } }, ["param2"] = 0, ["y"] = 2, ["param1"] = 12, ["z"] = 37, ["name"] = "default:water_source" }, { ["x"] = 2, ["meta"] = { ["fields"] = {  }, ["inventory"] = {  } }, ["param2"] = 0, ["y"] = 2, ["param1"] = 12, ["z"] = 38, ["name"] = "default:water_source" }, { ["x"] = 2, ["meta"] = { ["fields"] = {  }, ["inventory"] = {  } }, ["param2"] = 0, ["y"] = 2, ["param1"] = 12, ["z"] = 39, ["name"] = "default:water_source" }, { ["x"] = 2, ["meta"] = { ["fields"] = {  }, ["inventory"] = {  } }, ["param2"] = 0, ["y"] = 2, ["param1"] = 12, ["z"] = 40, ["name"] = "default:water_source" }, { ["x"] = 2, ["meta"] = { ["fields"] = {  }, ["inventory"] = {  } }, ["param2"] = 0, ["y"] = 2, ["param1"] = 12, ["z"] = 41, ["name"] = "default:water_source" }, { ["x"] = 2, ["meta"] = { ["fields"] = {  }, ["inventory"] = {  } }, ["param2"] = 0, ["y"] = 3, ["param1"] = 13, ["z"] = 0, ["name"] = "default:water_source" }, { ["x"] = 2, ["meta"] = { ["fields"] = {  }, ["inventory"] = {  } }, ["param2"] = 0, ["y"] = 3, ["param1"] = 13, ["z"] = 1, ["name"] = "default:water_source" }, { ["x"] = 2, ["meta"] = { ["fields"] = {  }, ["inventory"] = {  } }, ["param2"] = 0, ["y"] = 3, ["param1"] = 13, ["z"] = 2, ["name"] = "default:water_source" }, { ["x"] = 2, ["meta"] = { ["fields"] = {  }, ["inventory"] = {  } }, ["param2"] = 0, ["y"] = 3, ["param1"] = 13, ["z"] = 3, ["name"] = "default:water_source" }, { ["x"] = 2, ["meta"] = { ["fields"] = {  }, ["inventory"] = {  } }, ["param2"] = 0, ["y"] = 3, ["param1"] = 13, ["z"] = 4, ["name"] = "default:water_source" }, { ["x"] = 2, ["meta"] = { ["fields"] = {  }, ["inventory"] = {  } }, ["param2"] = 0, ["y"] = 3, ["param1"] = 13, ["z"] = 5, ["name"] = "default:water_source" }, { ["x"] = 2, ["meta"] = { ["fields"] = {  }, ["inventory"] = {  } }, ["param2"] = 0, ["y"] = 3, ["param1"] = 13, ["z"] = 6, ["name"] = "default:water_source" }, { ["x"] = 2, ["meta"] = { ["fields"] = {  }, ["inventory"] = {  } }, ["param2"] = 0, ["y"] = 3, ["param1"] = 13, ["z"] = 7, ["name"] = "default:water_source" }, { ["x"] = 2, ["meta"] = { ["fields"] = {  }, ["inventory"] = {  } }, ["param2"] = 0, ["y"] = 3, ["param1"] = 13, ["z"] = 8, ["name"] = "default:water_source" }, { ["x"] = 2, ["meta"] = { ["fields"] = {  }, ["inventory"] = {  } }, ["param2"] = 0, ["y"] = 3, ["param1"] = 13, ["z"] = 9, ["name"] = "default:water_source" }, { ["x"] = 2, ["meta"] = { ["fields"] = {  }, ["inventory"] = {  } }, ["param2"] = 0, ["y"] = 3, ["param1"] = 13, ["z"] = 10, ["name"] = "default:water_source" }, { ["x"] = 2, ["meta"] = { ["fields"] = {  }, ["inventory"] = {  } }, ["param2"] = 0, ["y"] = 3, ["param1"] = 13, ["z"] = 11, ["name"] = "default:water_source" }, { ["x"] = 2, ["meta"] = { ["fields"] = {  }, ["inventory"] = {  } }, ["param2"] = 0, ["y"] = 3, ["param1"] = 13, ["z"] = 12, ["name"] = "default:water_source" }, { ["x"] = 2, ["meta"] = { ["fields"] = {  }, ["inventory"] = {  } }, ["param2"] = 0, ["y"] = 3, ["param1"] = 13, ["z"] = 13, ["name"] = "default:water_source" }, { ["x"] = 2, ["meta"] = { ["fields"] = {  }, ["inventory"] = {  } }, ["param2"] = 0, ["y"] = 3, ["param1"] = 13, ["z"] = 14, ["name"] = "default:water_source" }, { ["x"] = 2, ["meta"] = { ["fields"] = {  }, ["inventory"] = {  } }, ["param2"] = 0, ["y"] = 3, ["param1"] = 13, ["z"] = 15, ["name"] = "default:water_source" }, { ["x"] = 2, ["meta"] = { ["fields"] = {  }, ["inventory"] = {  } }, ["param2"] = 0, ["y"] = 3, ["param1"] = 13, ["z"] = 16, ["name"] = "default:water_source" }, { ["x"] = 2, ["meta"] = { ["fields"] = {  }, ["inventory"] = {  } }, ["param2"] = 0, ["y"] = 3, ["param1"] = 13, ["z"] = 17, ["name"] = "default:water_source" }, { ["x"] = 2, ["meta"] = { ["fields"] = {  }, ["inventory"] = {  } }, ["param2"] = 0, ["y"] = 3, ["param1"] = 13, ["z"] = 18, ["name"] = "default:water_source" }, { ["x"] = 2, ["meta"] = { ["fields"] = {  }, ["inventory"] = {  } }, ["param2"] = 0, ["y"] = 3, ["param1"] = 13, ["z"] = 19, ["name"] = "default:water_source" }, { ["x"] = 2, ["meta"] = { ["fields"] = {  }, ["inventory"] = {  } }, ["param2"] = 0, ["y"] = 3, ["param1"] = 13, ["z"] = 20, ["name"] = "default:water_source" }, { ["x"] = 2, ["meta"] = { ["fields"] = {  }, ["inventory"] = {  } }, ["param2"] = 0, ["y"] = 3, ["param1"] = 13, ["z"] = 21, ["name"] = "default:water_source" }, { ["x"] = 2, ["meta"] = { ["fields"] = {  }, ["inventory"] = {  } }, ["param2"] = 0, ["y"] = 3, ["param1"] = 13, ["z"] = 22, ["name"] = "default:water_source" }, { ["x"] = 2, ["meta"] = { ["fields"] = {  }, ["inventory"] = {  } }, ["param2"] = 0, ["y"] = 3, ["param1"] = 13, ["z"] = 23, ["name"] = "default:water_source" }, { ["x"] = 2, ["meta"] = { ["fields"] = {  }, ["inventory"] = {  } }, ["param2"] = 0, ["y"] = 3, ["param1"] = 13, ["z"] = 24, ["name"] = "default:water_source" }, { ["x"] = 2, ["meta"] = { ["fields"] = {  }, ["inventory"] = {  } }, ["param2"] = 0, ["y"] = 3, ["param1"] = 13, ["z"] = 25, ["name"] = "default:water_source" }, { ["x"] = 2, ["meta"] = { ["fields"] = {  }, ["inventory"] = {  } }, ["param2"] = 0, ["y"] = 3, ["param1"] = 13, ["z"] = 26, ["name"] = "default:water_source" }, { ["x"] = 2, ["meta"] = { ["fields"] = {  }, ["inventory"] = {  } }, ["param2"] = 0, ["y"] = 3, ["param1"] = 13, ["z"] = 27, ["name"] = "default:water_source" }, { ["x"] = 2, ["meta"] = { ["fields"] = {  }, ["inventory"] = {  } }, ["param2"] = 0, ["y"] = 3, ["param1"] = 13, ["z"] = 28, ["name"] = "default:water_source" }, { ["x"] = 2, ["meta"] = { ["fields"] = {  }, ["inventory"] = {  } }, ["param2"] = 0, ["y"] = 3, ["param1"] = 13, ["z"] = 29, ["name"] = "default:water_source" }, { ["x"] = 2, ["meta"] = { ["fields"] = {  }, ["inventory"] = {  } }, ["param2"] = 0, ["y"] = 3, ["param1"] = 13, ["z"] = 30, ["name"] = "default:water_source" }, { ["x"] = 2, ["meta"] = { ["fields"] = {  }, ["inventory"] = {  } }, ["param2"] = 0, ["y"] = 3, ["param1"] = 13, ["z"] = 31, ["name"] = "default:water_source" }, { ["x"] = 2, ["meta"] = { ["fields"] = {  }, ["inventory"] = {  } }, ["param2"] = 0, ["y"] = 3, ["param1"] = 13, ["z"] = 32, ["name"] = "default:water_source" }, { ["x"] = 2, ["meta"] = { ["fields"] = {  }, ["inventory"] = {  } }, ["param2"] = 0, ["y"] = 3, ["param1"] = 13, ["z"] = 33, ["name"] = "default:water_source" }, { ["x"] = 2, ["meta"] = { ["fields"] = {  }, ["inventory"] = {  } }, ["param2"] = 0, ["y"] = 3, ["param1"] = 13, ["z"] = 34, ["name"] = "default:water_source" }, { ["x"] = 2, ["meta"] = { ["fields"] = {  }, ["inventory"] = {  } }, ["param2"] = 0, ["y"] = 3, ["param1"] = 13, ["z"] = 35, ["name"] = "default:water_source" }, { ["x"] = 2, ["meta"] = { ["fields"] = {  }, ["inventory"] = {  } }, ["param2"] = 0, ["y"] = 3, ["param1"] = 13, ["z"] = 36, ["name"] = "default:water_source" }, { ["x"] = 2, ["meta"] = { ["fields"] = {  }, ["inventory"] = {  } }, ["param2"] = 0, ["y"] = 3, ["param1"] = 13, ["z"] = 37, ["name"] = "default:water_source" }, { ["x"] = 2, ["meta"] = { ["fields"] = {  }, ["inventory"] = {  } }, ["param2"] = 0, ["y"] = 3, ["param1"] = 13, ["z"] = 38, ["name"] = "default:water_source" }, { ["x"] = 2, ["meta"] = { ["fields"] = {  }, ["inventory"] = {  } }, ["param2"] = 0, ["y"] = 3, ["param1"] = 13, ["z"] = 39, ["name"] = "default:water_source" }, { ["x"] = 2, ["meta"] = { ["fields"] = {  }, ["inventory"] = {  } }, ["param2"] = 0, ["y"] = 3, ["param1"] = 13, ["z"] = 40, ["name"] = "default:water_source" }, { ["x"] = 2, ["meta"] = { ["fields"] = {  }, ["inventory"] = {  } }, ["param2"] = 0, ["y"] = 3, ["param1"] = 13, ["z"] = 41, ["name"] = "default:water_source" }, { ["x"] = 3, ["meta"] = { ["fields"] = {  }, ["inventory"] = {  } }, ["param2"] = 0, ["y"] = 0, ["param1"] = 10, ["z"] = 0, ["name"] = "default:water_source" }, { ["x"] = 3, ["meta"] = { ["fields"] = {  }, ["inventory"] = {  } }, ["param2"] = 0, ["y"] = 0, ["param1"] = 10, ["z"] = 1, ["name"] = "default:water_source" }, { ["x"] = 3, ["meta"] = { ["fields"] = {  }, ["inventory"] = {  } }, ["param2"] = 0, ["y"] = 0, ["param1"] = 10, ["z"] = 2, ["name"] = "default:water_source" }, { ["x"] = 3, ["meta"] = { ["fields"] = {  }, ["inventory"] = {  } }, ["param2"] = 0, ["y"] = 0, ["param1"] = 10, ["z"] = 3, ["name"] = "default:water_source" }, { ["x"] = 3, ["meta"] = { ["fields"] = {  }, ["inventory"] = {  } }, ["param2"] = 0, ["y"] = 0, ["param1"] = 10, ["z"] = 4, ["name"] = "default:water_source" }, { ["x"] = 3, ["meta"] = { ["fields"] = {  }, ["inventory"] = {  } }, ["param2"] = 0, ["y"] = 0, ["param1"] = 10, ["z"] = 5, ["name"] = "default:water_source" }, { ["x"] = 3, ["meta"] = { ["fields"] = {  }, ["inventory"] = {  } }, ["param2"] = 0, ["y"] = 0, ["param1"] = 10, ["z"] = 6, ["name"] = "default:water_source" }, { ["x"] = 3, ["meta"] = { ["fields"] = {  }, ["inventory"] = {  } }, ["param2"] = 240, ["y"] = 0, ["param1"] = 10, ["z"] = 7, ["name"] = "default:water_source" }, { ["x"] = 3, ["meta"] = { ["fields"] = {  }, ["inventory"] = {  } }, ["param2"] = 240, ["y"] = 0, ["param1"] = 10, ["z"] = 8, ["name"] = "default:water_source" }, { ["x"] = 3, ["meta"] = { ["fields"] = {  }, ["inventory"] = {  } }, ["param2"] = 240, ["y"] = 0, ["param1"] = 10, ["z"] = 9, ["name"] = "default:water_source" }, { ["x"] = 3, ["meta"] = { ["fields"] = {  }, ["inventory"] = {  } }, ["param2"] = 240, ["y"] = 0, ["param1"] = 10, ["z"] = 10, ["name"] = "default:water_source" }, { ["x"] = 3, ["meta"] = { ["fields"] = {  }, ["inventory"] = {  } }, ["param2"] = 240, ["y"] = 0, ["param1"] = 10, ["z"] = 11, ["name"] = "default:water_source" }, { ["x"] = 3, ["meta"] = { ["fields"] = {  }, ["inventory"] = {  } }, ["param2"] = 240, ["y"] = 0, ["param1"] = 10, ["z"] = 12, ["name"] = "default:water_source" }, { ["x"] = 3, ["meta"] = { ["fields"] = {  }, ["inventory"] = {  } }, ["param2"] = 240, ["y"] = 0, ["param1"] = 10, ["z"] = 13, ["name"] = "default:water_source" }, { ["x"] = 3, ["meta"] = { ["fields"] = {  }, ["inventory"] = {  } }, ["param2"] = 240, ["y"] = 0, ["param1"] = 10, ["z"] = 14, ["name"] = "default:water_source" }, { ["x"] = 3, ["meta"] = { ["fields"] = {  }, ["inventory"] = {  } }, ["param2"] = 240, ["y"] = 0, ["param1"] = 10, ["z"] = 15, ["name"] = "default:water_source" }, { ["x"] = 3, ["meta"] = { ["fields"] = {  }, ["inventory"] = {  } }, ["param2"] = 240, ["y"] = 0, ["param1"] = 10, ["z"] = 16, ["name"] = "default:water_source" }, { ["x"] = 3, ["meta"] = { ["fields"] = {  }, ["inventory"] = {  } }, ["param2"] = 240, ["y"] = 0, ["param1"] = 10, ["z"] = 17, ["name"] = "default:water_source" }, { ["x"] = 3, ["meta"] = { ["fields"] = {  }, ["inventory"] = {  } }, ["param2"] = 240, ["y"] = 0, ["param1"] = 10, ["z"] = 18, ["name"] = "default:water_source" }, { ["x"] = 3, ["meta"] = { ["fields"] = {  }, ["inventory"] = {  } }, ["param2"] = 240, ["y"] = 0, ["param1"] = 10, ["z"] = 19, ["name"] = "default:water_source" }, { ["x"] = 3, ["meta"] = { ["fields"] = {  }, ["inventory"] = {  } }, ["param2"] = 240, ["y"] = 0, ["param1"] = 10, ["z"] = 20, ["name"] = "default:water_source" }, { ["x"] = 3, ["meta"] = { ["fields"] = {  }, ["inventory"] = {  } }, ["param2"] = 240, ["y"] = 0, ["param1"] = 9, ["z"] = 21, ["name"] = "default:water_source" }, { ["x"] = 3, ["meta"] = { ["fields"] = {  }, ["inventory"] = {  } }, ["param2"] = 240, ["y"] = 0, ["param1"] = 9, ["z"] = 22, ["name"] = "default:water_source" }, { ["x"] = 3, ["meta"] = { ["fields"] = {  }, ["inventory"] = {  } }, ["param2"] = 240, ["y"] = 0, ["param1"] = 10, ["z"] = 23, ["name"] = "default:water_source" }, { ["x"] = 3, ["meta"] = { ["fields"] = {  }, ["inventory"] = {  } }, ["param2"] = 240, ["y"] = 0, ["param1"] = 10, ["z"] = 24, ["name"] = "default:water_source" }, { ["x"] = 3, ["meta"] = { ["fields"] = {  }, ["inventory"] = {  } }, ["param2"] = 240, ["y"] = 0, ["param1"] = 10, ["z"] = 25, ["name"] = "default:water_source" }, { ["x"] = 3, ["meta"] = { ["fields"] = {  }, ["inventory"] = {  } }, ["param2"] = 240, ["y"] = 0, ["param1"] = 10, ["z"] = 26, ["name"] = "default:water_source" }, { ["x"] = 3, ["meta"] = { ["fields"] = {  }, ["inventory"] = {  } }, ["param2"] = 240, ["y"] = 0, ["param1"] = 10, ["z"] = 27, ["name"] = "default:water_source" }, { ["x"] = 3, ["meta"] = { ["fields"] = {  }, ["inventory"] = {  } }, ["param2"] = 240, ["y"] = 0, ["param1"] = 10, ["z"] = 28, ["name"] = "default:water_source" }, { ["x"] = 3, ["meta"] = { ["fields"] = {  }, ["inventory"] = {  } }, ["param2"] = 240, ["y"] = 0, ["param1"] = 10, ["z"] = 29, ["name"] = "default:water_source" }, { ["x"] = 3, ["meta"] = { ["fields"] = {  }, ["inventory"] = {  } }, ["param2"] = 240, ["y"] = 0, ["param1"] = 10, ["z"] = 30, ["name"] = "default:water_source" }, { ["x"] = 3, ["meta"] = { ["fields"] = {  }, ["inventory"] = {  } }, ["param2"] = 240, ["y"] = 0, ["param1"] = 10, ["z"] = 31, ["name"] = "default:water_source" }, { ["x"] = 3, ["meta"] = { ["fields"] = {  }, ["inventory"] = {  } }, ["param2"] = 240, ["y"] = 0, ["param1"] = 10, ["z"] = 32, ["name"] = "default:water_source" }, { ["x"] = 3, ["meta"] = { ["fields"] = {  }, ["inventory"] = {  } }, ["param2"] = 240, ["y"] = 0, ["param1"] = 10, ["z"] = 33, ["name"] = "default:water_source" }, { ["x"] = 3, ["meta"] = { ["fields"] = {  }, ["inventory"] = {  } }, ["param2"] = 240, ["y"] = 0, ["param1"] = 10, ["z"] = 34, ["name"] = "default:water_source" }, { ["x"] = 3, ["meta"] = { ["fields"] = {  }, ["inventory"] = {  } }, ["param2"] = 0, ["y"] = 0, ["param1"] = 10, ["z"] = 35, ["name"] = "default:water_source" }, { ["x"] = 3, ["meta"] = { ["fields"] = {  }, ["inventory"] = {  } }, ["param2"] = 0, ["y"] = 0, ["param1"] = 10, ["z"] = 36, ["name"] = "default:water_source" }, { ["x"] = 3, ["meta"] = { ["fields"] = {  }, ["inventory"] = {  } }, ["param2"] = 0, ["y"] = 0, ["param1"] = 10, ["z"] = 37, ["name"] = "default:water_source" }, { ["x"] = 3, ["meta"] = { ["fields"] = {  }, ["inventory"] = {  } }, ["param2"] = 0, ["y"] = 0, ["param1"] = 10, ["z"] = 38, ["name"] = "default:water_source" }, { ["x"] = 3, ["meta"] = { ["fields"] = {  }, ["inventory"] = {  } }, ["param2"] = 0, ["y"] = 0, ["param1"] = 10, ["z"] = 39, ["name"] = "default:water_source" }, { ["x"] = 3, ["meta"] = { ["fields"] = {  }, ["inventory"] = {  } }, ["param2"] = 0, ["y"] = 0, ["param1"] = 10, ["z"] = 40, ["name"] = "default:water_source" }, { ["x"] = 3, ["meta"] = { ["fields"] = {  }, ["inventory"] = {  } }, ["param2"] = 0, ["y"] = 0, ["param1"] = 10, ["z"] = 41, ["name"] = "default:water_source" }, { ["x"] = 3, ["meta"] = { ["fields"] = {  }, ["inventory"] = {  } }, ["param2"] = 0, ["y"] = 1, ["param1"] = 11, ["z"] = 0, ["name"] = "default:water_source" }, { ["x"] = 3, ["meta"] = { ["fields"] = {  }, ["inventory"] = {  } }, ["param2"] = 0, ["y"] = 1, ["param1"] = 11, ["z"] = 1, ["name"] = "default:water_source" }, { ["x"] = 3, ["meta"] = { ["fields"] = {  }, ["inventory"] = {  } }, ["param2"] = 0, ["y"] = 1, ["param1"] = 11, ["z"] = 2, ["name"] = "default:water_source" }, { ["x"] = 3, ["meta"] = { ["fields"] = {  }, ["inventory"] = {  } }, ["param2"] = 0, ["y"] = 1, ["param1"] = 11, ["z"] = 3, ["name"] = "default:water_source" }, { ["x"] = 3, ["meta"] = { ["fields"] = {  }, ["inventory"] = {  } }, ["param2"] = 0, ["y"] = 1, ["param1"] = 11, ["z"] = 4, ["name"] = "default:water_source" }, { ["x"] = 3, ["meta"] = { ["fields"] = {  }, ["inventory"] = {  } }, ["param2"] = 0, ["y"] = 1, ["param1"] = 11, ["z"] = 5, ["name"] = "default:water_source" }, { ["x"] = 3, ["meta"] = { ["fields"] = {  }, ["inventory"] = {  } }, ["param2"] = 0, ["y"] = 1, ["param1"] = 11, ["z"] = 6, ["name"] = "default:water_source" }, { ["x"] = 3, ["meta"] = { ["fields"] = {  }, ["inventory"] = {  } }, ["param2"] = 240, ["y"] = 1, ["param1"] = 11, ["z"] = 7, ["name"] = "default:water_source" }, { ["x"] = 3, ["meta"] = { ["fields"] = {  }, ["inventory"] = {  } }, ["param2"] = 240, ["y"] = 1, ["param1"] = 11, ["z"] = 8, ["name"] = "default:water_source" }, { ["x"] = 3, ["meta"] = { ["fields"] = {  }, ["inventory"] = {  } }, ["param2"] = 240, ["y"] = 1, ["param1"] = 11, ["z"] = 9, ["name"] = "default:water_source" }, { ["x"] = 3, ["meta"] = { ["fields"] = {  }, ["inventory"] = {  } }, ["param2"] = 240, ["y"] = 1, ["param1"] = 11, ["z"] = 10, ["name"] = "default:water_source" }, { ["x"] = 3, ["meta"] = { ["fields"] = {  }, ["inventory"] = {  } }, ["param2"] = 240, ["y"] = 1, ["param1"] = 11, ["z"] = 11, ["name"] = "default:water_source" }, { ["x"] = 3, ["meta"] = { ["fields"] = {  }, ["inventory"] = {  } }, ["param2"] = 240, ["y"] = 1, ["param1"] = 11, ["z"] = 12, ["name"] = "default:water_source" }, { ["x"] = 3, ["meta"] = { ["fields"] = {  }, ["inventory"] = {  } }, ["param2"] = 240, ["y"] = 1, ["param1"] = 11, ["z"] = 13, ["name"] = "default:water_source" }, { ["x"] = 3, ["meta"] = { ["fields"] = {  }, ["inventory"] = {  } }, ["param2"] = 240, ["y"] = 1, ["param1"] = 11, ["z"] = 14, ["name"] = "default:water_source" }, { ["x"] = 3, ["meta"] = { ["fields"] = {  }, ["inventory"] = {  } }, ["param2"] = 240, ["y"] = 1, ["param1"] = 11, ["z"] = 15, ["name"] = "default:water_source" }, { ["x"] = 3, ["meta"] = { ["fields"] = {  }, ["inventory"] = {  } }, ["param2"] = 240, ["y"] = 1, ["param1"] = 11, ["z"] = 16, ["name"] = "default:water_source" }, { ["x"] = 3, ["meta"] = { ["fields"] = {  }, ["inventory"] = {  } }, ["param2"] = 240, ["y"] = 1, ["param1"] = 11, ["z"] = 17, ["name"] = "default:water_source" }, { ["x"] = 3, ["meta"] = { ["fields"] = {  }, ["inventory"] = {  } }, ["param2"] = 240, ["y"] = 1, ["param1"] = 11, ["z"] = 18, ["name"] = "default:water_source" }, { ["x"] = 3, ["meta"] = { ["fields"] = {  }, ["inventory"] = {  } }, ["param2"] = 240, ["y"] = 1, ["param1"] = 11, ["z"] = 19, ["name"] = "default:water_source" }, { ["x"] = 3, ["meta"] = { ["fields"] = {  }, ["inventory"] = {  } }, ["param2"] = 240, ["y"] = 1, ["param1"] = 11, ["z"] = 20, ["name"] = "default:water_source" }, { ["x"] = 3, ["meta"] = { ["fields"] = {  }, ["inventory"] = {  } }, ["param2"] = 240, ["y"] = 1, ["param1"] = 10, ["z"] = 21, ["name"] = "default:water_source" }, { ["x"] = 3, ["meta"] = { ["fields"] = {  }, ["inventory"] = {  } }, ["param2"] = 240, ["y"] = 1, ["param1"] = 10, ["z"] = 22, ["name"] = "default:water_source" }, { ["x"] = 3, ["meta"] = { ["fields"] = {  }, ["inventory"] = {  } }, ["param2"] = 240, ["y"] = 1, ["param1"] = 11, ["z"] = 23, ["name"] = "default:water_source" }, { ["x"] = 3, ["meta"] = { ["fields"] = {  }, ["inventory"] = {  } }, ["param2"] = 240, ["y"] = 1, ["param1"] = 11, ["z"] = 24, ["name"] = "default:water_source" }, { ["x"] = 3, ["meta"] = { ["fields"] = {  }, ["inventory"] = {  } }, ["param2"] = 240, ["y"] = 1, ["param1"] = 11, ["z"] = 25, ["name"] = "default:water_source" }, { ["x"] = 3, ["meta"] = { ["fields"] = {  }, ["inventory"] = {  } }, ["param2"] = 240, ["y"] = 1, ["param1"] = 11, ["z"] = 26, ["name"] = "default:water_source" }, { ["x"] = 3, ["meta"] = { ["fields"] = {  }, ["inventory"] = {  } }, ["param2"] = 240, ["y"] = 1, ["param1"] = 11, ["z"] = 27, ["name"] = "default:water_source" }, { ["x"] = 3, ["meta"] = { ["fields"] = {  }, ["inventory"] = {  } }, ["param2"] = 240, ["y"] = 1, ["param1"] = 11, ["z"] = 28, ["name"] = "default:water_source" }, { ["x"] = 3, ["meta"] = { ["fields"] = {  }, ["inventory"] = {  } }, ["param2"] = 240, ["y"] = 1, ["param1"] = 11, ["z"] = 29, ["name"] = "default:water_source" }, { ["x"] = 3, ["meta"] = { ["fields"] = {  }, ["inventory"] = {  } }, ["param2"] = 240, ["y"] = 1, ["param1"] = 11, ["z"] = 30, ["name"] = "default:water_source" }, { ["x"] = 3, ["meta"] = { ["fields"] = {  }, ["inventory"] = {  } }, ["param2"] = 240, ["y"] = 1, ["param1"] = 11, ["z"] = 31, ["name"] = "default:water_source" }, { ["x"] = 3, ["meta"] = { ["fields"] = {  }, ["inventory"] = {  } }, ["param2"] = 240, ["y"] = 1, ["param1"] = 11, ["z"] = 32, ["name"] = "default:water_source" }, { ["x"] = 3, ["meta"] = { ["fields"] = {  }, ["inventory"] = {  } }, ["param2"] = 240, ["y"] = 1, ["param1"] = 11, ["z"] = 33, ["name"] = "default:water_source" }, { ["x"] = 3, ["meta"] = { ["fields"] = {  }, ["inventory"] = {  } }, ["param2"] = 240, ["y"] = 1, ["param1"] = 11, ["z"] = 34, ["name"] = "default:water_source" }, { ["x"] = 3, ["meta"] = { ["fields"] = {  }, ["inventory"] = {  } }, ["param2"] = 0, ["y"] = 1, ["param1"] = 11, ["z"] = 35, ["name"] = "default:water_source" }, { ["x"] = 3, ["meta"] = { ["fields"] = {  }, ["inventory"] = {  } }, ["param2"] = 0, ["y"] = 1, ["param1"] = 11, ["z"] = 36, ["name"] = "default:water_source" }, { ["x"] = 3, ["meta"] = { ["fields"] = {  }, ["inventory"] = {  } }, ["param2"] = 0, ["y"] = 1, ["param1"] = 11, ["z"] = 37, ["name"] = "default:water_source" }, { ["x"] = 3, ["meta"] = { ["fields"] = {  }, ["inventory"] = {  } }, ["param2"] = 0, ["y"] = 1, ["param1"] = 11, ["z"] = 38, ["name"] = "default:water_source" }, { ["x"] = 3, ["meta"] = { ["fields"] = {  }, ["inventory"] = {  } }, ["param2"] = 0, ["y"] = 1, ["param1"] = 11, ["z"] = 39, ["name"] = "default:water_source" }, { ["x"] = 3, ["meta"] = { ["fields"] = {  }, ["inventory"] = {  } }, ["param2"] = 0, ["y"] = 1, ["param1"] = 11, ["z"] = 40, ["name"] = "default:water_source" }, { ["x"] = 3, ["meta"] = { ["fields"] = {  }, ["inventory"] = {  } }, ["param2"] = 0, ["y"] = 1, ["param1"] = 11, ["z"] = 41, ["name"] = "default:water_source" }, { ["x"] = 3, ["meta"] = { ["fields"] = {  }, ["inventory"] = {  } }, ["param2"] = 0, ["y"] = 2, ["param1"] = 12, ["z"] = 0, ["name"] = "default:water_source" }, { ["x"] = 3, ["meta"] = { ["fields"] = {  }, ["inventory"] = {  } }, ["param2"] = 0, ["y"] = 2, ["param1"] = 12, ["z"] = 1, ["name"] = "default:water_source" }, { ["x"] = 3, ["meta"] = { ["fields"] = {  }, ["inventory"] = {  } }, ["param2"] = 0, ["y"] = 2, ["param1"] = 12, ["z"] = 2, ["name"] = "default:water_source" }, { ["x"] = 3, ["meta"] = { ["fields"] = {  }, ["inventory"] = {  } }, ["param2"] = 0, ["y"] = 2, ["param1"] = 12, ["z"] = 3, ["name"] = "default:water_source" }, { ["x"] = 3, ["meta"] = { ["fields"] = {  }, ["inventory"] = {  } }, ["param2"] = 0, ["y"] = 2, ["param1"] = 12, ["z"] = 4, ["name"] = "default:water_source" }, { ["x"] = 3, ["meta"] = { ["fields"] = {  }, ["inventory"] = {  } }, ["param2"] = 0, ["y"] = 2, ["param1"] = 12, ["z"] = 5, ["name"] = "default:water_source" }, { ["x"] = 3, ["meta"] = { ["fields"] = {  }, ["inventory"] = {  } }, ["param2"] = 0, ["y"] = 2, ["param1"] = 12, ["z"] = 6, ["name"] = "default:water_source" }, { ["x"] = 3, ["meta"] = { ["fields"] = {  }, ["inventory"] = {  } }, ["param2"] = 0, ["y"] = 2, ["param1"] = 12, ["z"] = 7, ["name"] = "default:water_source" }, { ["x"] = 3, ["meta"] = { ["fields"] = {  }, ["inventory"] = {  } }, ["param2"] = 0, ["y"] = 2, ["param1"] = 12, ["z"] = 8, ["name"] = "default:water_source" }, { ["x"] = 3, ["meta"] = { ["fields"] = {  }, ["inventory"] = {  } }, ["param2"] = 0, ["y"] = 2, ["param1"] = 12, ["z"] = 9, ["name"] = "default:water_source" }, { ["x"] = 3, ["meta"] = { ["fields"] = {  }, ["inventory"] = {  } }, ["param2"] = 0, ["y"] = 2, ["param1"] = 12, ["z"] = 10, ["name"] = "default:water_source" }, { ["x"] = 3, ["meta"] = { ["fields"] = {  }, ["inventory"] = {  } }, ["param2"] = 0, ["y"] = 2, ["param1"] = 12, ["z"] = 11, ["name"] = "default:water_source" }, { ["x"] = 3, ["meta"] = { ["fields"] = {  }, ["inventory"] = {  } }, ["param2"] = 0, ["y"] = 2, ["param1"] = 12, ["z"] = 12, ["name"] = "default:water_source" }, { ["x"] = 3, ["meta"] = { ["fields"] = {  }, ["inventory"] = {  } }, ["param2"] = 0, ["y"] = 2, ["param1"] = 12, ["z"] = 13, ["name"] = "default:water_source" }, { ["x"] = 3, ["meta"] = { ["fields"] = {  }, ["inventory"] = {  } }, ["param2"] = 0, ["y"] = 2, ["param1"] = 12, ["z"] = 14, ["name"] = "default:water_source" }, { ["x"] = 3, ["meta"] = { ["fields"] = {  }, ["inventory"] = {  } }, ["param2"] = 0, ["y"] = 2, ["param1"] = 12, ["z"] = 15, ["name"] = "default:water_source" }, { ["x"] = 3, ["meta"] = { ["fields"] = {  }, ["inventory"] = {  } }, ["param2"] = 0, ["y"] = 2, ["param1"] = 12, ["z"] = 16, ["name"] = "default:water_source" }, { ["x"] = 3, ["meta"] = { ["fields"] = {  }, ["inventory"] = {  } }, ["param2"] = 0, ["y"] = 2, ["param1"] = 12, ["z"] = 17, ["name"] = "default:water_source" }, { ["x"] = 3, ["meta"] = { ["fields"] = {  }, ["inventory"] = {  } }, ["param2"] = 0, ["y"] = 2, ["param1"] = 12, ["z"] = 18, ["name"] = "default:water_source" }, { ["x"] = 3, ["meta"] = { ["fields"] = {  }, ["inventory"] = {  } }, ["param2"] = 0, ["y"] = 2, ["param1"] = 12, ["z"] = 19, ["name"] = "default:water_source" }, { ["x"] = 3, ["meta"] = { ["fields"] = {  }, ["inventory"] = {  } }, ["param2"] = 0, ["y"] = 2, ["param1"] = 12, ["z"] = 20, ["name"] = "default:water_source" }, { ["x"] = 3, ["meta"] = { ["fields"] = {  }, ["inventory"] = {  } }, ["param2"] = 0, ["y"] = 2, ["param1"] = 11, ["z"] = 21, ["name"] = "default:water_source" }, { ["x"] = 3, ["meta"] = { ["fields"] = {  }, ["inventory"] = {  } }, ["param2"] = 0, ["y"] = 2, ["param1"] = 11, ["z"] = 22, ["name"] = "default:water_source" }, { ["x"] = 3, ["meta"] = { ["fields"] = {  }, ["inventory"] = {  } }, ["param2"] = 0, ["y"] = 2, ["param1"] = 12, ["z"] = 23, ["name"] = "default:water_source" }, { ["x"] = 3, ["meta"] = { ["fields"] = {  }, ["inventory"] = {  } }, ["param2"] = 0, ["y"] = 2, ["param1"] = 12, ["z"] = 24, ["name"] = "default:water_source" }, { ["x"] = 3, ["meta"] = { ["fields"] = {  }, ["inventory"] = {  } }, ["param2"] = 0, ["y"] = 2, ["param1"] = 12, ["z"] = 25, ["name"] = "default:water_source" }, { ["x"] = 3, ["meta"] = { ["fields"] = {  }, ["inventory"] = {  } }, ["param2"] = 0, ["y"] = 2, ["param1"] = 12, ["z"] = 26, ["name"] = "default:water_source" }, { ["x"] = 3, ["meta"] = { ["fields"] = {  },